Workbook

Sheet Table of content
A4: Table of content
A5: Spreadsheet title | B5: Description
A6: Reference data -- material list
A7: Materials | B7: List of materials covered
A8: Red sheet represent data used for the material limits in EnergyScope
A9: Material_limits | B9: Material limits in tons per year, per material, every 5 years from 2020 to 2050.
A10: Red sheet represent data used for the material limits in EnergyScope
A11: RoE_Demand | B11: Material demand from the rest of economy in % until 2050. Most values are hypothesis
A12: Yellow spreadsheets represent study results
A13: MiningCapacity_Calcul | B13: Production in 2020 by metal in tons by year, with specification of the mining flow considered
B14: Estimation of beta, the median of historical production growth, by metals, used to project future metal production until 2050. Specification of the historical production years used for each metal to estimate beta. Hypothesis of future production rate for each metal. Beta of the metals added in this version (Iridium, Lanthanum, Magnesium, Palladium, Platinum) is linked to the Calcul_Prod spreadsheet.
B15: IEA estimation of production between 2020 and 2040 in tons per year for cobalt, copper, nickel and lithium. Beta projection used between 2040 and 2050.
B16: By-product content hypothesis from the major host for cadmium, gallium, germanium, indium, selenium and tellurium
A17: Reserves_Resources_RR | B17: Reserve and resources estimates in tons per metal, with confidence level and reference.
B18: Recovery rates by metal in percentage (Charpentier Poncelet et al., 2022): RR_Refining compares the metal in the final product to the production state; RR_Mining_Refining compares it to the mining state (see Ref&Hp for the calculation rule).
A19: MiningCapacity_Results | B19: Global primary mining capacity in tons per year for decades from 2020 to 2050 per metal: Primary_Production = production 2020 × (1 + beta)^(t − 2020) × RR_Refining (IEA data for Co, Cu, Ni, Li until 2040; by-product ratio for by-products).
A20: Dark grey spreadsheet represent reference and hypothesis of calculation
A21: Ref&Hp | B21: The references of each spreadsheet is organized in this file in a table, by spreadsheet name, followed by the hypothesis made.
A22: Calcul_Prod | B22: Table presenting calculation methods for future production. Includes historical data of production by metals (1913–2022), calculation of beta for each metal (mean and median of annual growth over three windows: all years, 1990–2022, 1990–2022 excluding the 2019–2020 covid years), by-product / host ratio estimates, and calculation of future by-product production based on the host one.

Sheet Materials
A1: Full_Name | B1: Short_Code
A2: Aluminum | B2: Al
A3: Boron | B3: B
A4: Cadmium | B4: Cd
A5: Chromium | B5: Cr
A6: Cobalt | B6: Co
A7: Concrete | B7: Concrete
A8: Copper | B8: Cu
A9: Dysprosium | B9: Dy
A10: Gallium | B10: Ga
A11: Germanium | B11: Ge
A12: Glass | B12: Glass
... A42: Zirconium | B42: Zr

Sheet Material_limits
A1: Material limits [t] | B1: 2020 | C1: 2025 | D1: 2030 | E1: 2035 | F1: 2040 | G1: 2045 | H1: 2050
A2: Aluminum | B2: =MiningCapacity_Results!C2*0.003*(1-RoE_Demand!B2) -> 44339.874 | C2: =MiningCapacity_Results!D2*0.003*(1-RoE_Demand!C2) -> 59673.352 | D2: =MiningCapacity_Results!E2*0.003*(1-RoE_Demand!D2) -> 80309.407 | E2: =MiningCapacity_Results!F2*0.003*(1-RoE_Demand!E2) -> 108081.76 | F2: =MiningCapacity_Results!G2*0.003*(1-RoE_Demand!F2) -> 145458.26 | G2: =MiningCapacity_Results!H2*0.003*(1-RoE_Demand!G2) -> 195760.18 | H2: =MiningCapacity_Results!I2*0.003*(1-RoE_Demand!H2) -> 263457.36
A3: Boron | B3: =MiningCapacity_Results!C3*0.003*(1-RoE_Demand!B3) -> 103.85257 | C3: =MiningCapacity_Results!D3*0.003*(1-RoE_Demand!C3) -> 132.36637 | D3: =MiningCapacity_Results!E3*0.003*(1-RoE_Demand!D3) -> 168.70894 | E3: =MiningCapacity_Results!F3*0.003*(1-RoE_Demand!E3) -> 215.02974 | F3: =MiningCapacity_Results!G3*0.003*(1-RoE_Demand!F3) -> 274.0684 | G3: =MiningCapacity_Results!H3*0.003*(1-RoE_Demand!G3) -> 349.31674 | H3: =MiningCapacity_Results!I3*0.003*(1-RoE_Demand!H3) -> 445.2253
A4: Cadmium | B4: =MiningCapacity_Results!C4*0.003*(1-RoE_Demand!B4) -> 0.64165236 | C4: =MiningCapacity_Results!D4*0.003*(1-RoE_Demand!C4) -> 0.76961076 | D4: =MiningCapacity_Results!E4*0.003*(1-RoE_Demand!D4) -> 0.92308665 | E4: =MiningCapacity_Results!F4*0.003*(1-RoE_Demand!E4) -> 1.1071687 | F4: =MiningCapacity_Results!G4*0.003*(1-RoE_Demand!F4) -> 1.3279604 | G4: =MiningCapacity_Results!H4*0.003*(1-RoE_Demand!G4) -> 1.5927825 | H4: =MiningCapacity_Results!I4*0.003*(1-RoE_Demand!H4) -> 1.9104154
A5: Chromium | B5: =MiningCapacity_Results!C5*0.003*(1-RoE_Demand!B5) -> 19806.378 | C5: =MiningCapacity_Results!D5*0.003*(1-RoE_Demand!C5) -> 27544.251 | D5: =MiningCapacity_Results!E5*0.003*(1-RoE_Demand!D5) -> 38305.125 | E5: =MiningCapacity_Results!F5*0.003*(1-RoE_Demand!E5) -> 53270.011 | F5: =MiningCapacity_Results!G5*0.003*(1-RoE_Demand!F5) -> 74081.317 | G5: =MiningCapacity_Results!H5*0.003*(1-RoE_Demand!G5) -> 103023.1 | H5: =MiningCapacity_Results!I5*0.003*(1-RoE_Demand!H5) -> 143271.73
A6: Cobalt | B6: =MiningCapacity_Results!C6*0.003*(1-RoE_Demand!B6) -> 183.18 | C6: =MiningCapacity_Results!D6*0.003*(1-RoE_Demand!C6) -> 323.79 | D6: =MiningCapacity_Results!E6*0.003*(1-RoE_Demand!D6) -> 615.6 | E6: =MiningCapacity_Results!F6*0.003*(1-RoE_Demand!E6) -> 529.245 | F6: =MiningCapacity_Results!G6*0.003*(1-RoE_Demand!F6) -> 442.89 | G6: =MiningCapacity_Results!H6*0.003*(1-RoE_Demand!G6) -> 647.74979 | H6: =MiningCapacity_Results!I6*0.003*(1-RoE_Demand!H6) -> 947.36795
A7: Concrete
A8: Copper | B8: =MiningCapacity_Results!C7*0.003*(1-RoE_Demand!B8) -> 12360 | C8: =MiningCapacity_Results!D7*0.003*(1-RoE_Demand!C8) -> 13470 | D8: =MiningCapacity_Results!E7*0.003*(1-RoE_Demand!D8) -> 14580 | E8: =MiningCapacity_Results!F7*0.003*(1-RoE_Demand!E8) -> 15337.5 | F8: =MiningCapacity_Results!G7*0.003*(1-RoE_Demand!F8) -> 12450 | G8: =MiningCapacity_Results!H7*0.003*(1-RoE_Demand!G8) -> 14178.561 | H8: =MiningCapacity_Results!I7*0.003*(1-RoE_Demand!H8) -> 16147.116
A9: Dysprosium | B9: =MiningCapacity_Results!C8*0.003*(1-RoE_Demand!B9) -> 0.84648176 | C9: =MiningCapacity_Results!D8*0.003*(1-RoE_Demand!C9) -> 1.3103797 | D9: =MiningCapacity_Results!E8*0.003*(1-RoE_Demand!D9) -> 1.9721604 | E9: =MiningCapacity_Results!F8*0.003*(1-RoE_Demand!E9) -> 2.9075854 | F9: =MiningCapacity_Results!G8*0.003*(1-RoE_Demand!F9) -> 4.2197168 | G9: =MiningCapacity_Results!H8*0.003*(1-RoE_Demand!G9) -> 6.0483804 | H9: =MiningCapacity_Results!I8*0.003*(1-RoE_Demand!H9) -> 8.5828215
A10: Gallium | B10: =MiningCapacity_Results!C9*0.003*(1-RoE_Demand!B10) -> 0.11688705 | C10: =MiningCapacity_Results!D9*0.003*(1-RoE_Demand!C10) -> 0.15730857 | D10: =MiningCapacity_Results!E9*0.003*(1-RoE_Demand!D10) -> 0.21170853 | E10: =MiningCapacity_Results!F9*0.003*(1-RoE_Demand!E10) -> 0.28492092 | F10: =MiningCapacity_Results!G9*0.003*(1-RoE_Demand!F10) -> 0.3834514 | G10: =MiningCapacity_Results!H9*0.003*(1-RoE_Demand!G10) -> 0.51605537 | H10: =MiningCapacity_Results!I9*0.003*(1-RoE_Demand!H10) -> 0.69451605
A11: Germanium | B11: =MiningCapacity_Results!C10*0.003*(1-RoE_Demand!B11) -> 0.062244 | C11: =MiningCapacity_Results!D10*0.003*(1-RoE_Demand!C11) -> 0.074656707 | D11: =MiningCapacity_Results!E10*0.003*(1-RoE_Demand!D11) -> 0.089544758 | E11: =MiningCapacity_Results!F10*0.003*(1-RoE_Demand!E11) -> 0.10740179 | F11: =MiningCapacity_Results!G10*0.003*(1-RoE_Demand!F11) -> 0.12881986 | G11: =MiningCapacity_Results!H10*0.003*(1-RoE_Demand!G11) -> 0.15450914 | H11: =MiningCapacity_Results!I10*0.003*(1-RoE_Demand!H11) -> 0.18532137
A12: Glass
A13: Hafnium | B13: =MiningCapacity_Results!C11*0.003*(1-RoE_Demand!B13) -> 0.011248471 | C13: =MiningCapacity_Results!D11*0.003*(1-RoE_Demand!C13) -> 0.015922775 | D13: =MiningCapacity_Results!E11*0.003*(1-RoE_Demand!D13) -> 0.022539487 | E13: =MiningCapacity_Results!F11*0.003*(1-RoE_Demand!E13) -> 0.031905774 | F13: =MiningCapacity_Results!G11*0.003*(1-RoE_Demand!F13) -> 0.045164223 | G13: =MiningCapacity_Results!H11*0.003*(1-RoE_Demand!G13) -> 0.063932222 | H13: =MiningCapacity_Results!I11*0.003*(1-RoE_Demand!H13) -> 0.090499266
A14: Indium | B14: =MiningCapacity_Results!C12*0.003*(1-RoE_Demand!B14) -> 0.2418 | C14: =MiningCapacity_Results!D12*0.003*(1-RoE_Demand!C14) -> 0.28326882 | D14: =MiningCapacity_Results!E12*0.003*(1-RoE_Demand!D14) -> 0.33184956 | E14: =MiningCapacity_Results!F12*0.003*(1-RoE_Demand!E14) -> 0.37436487 | F14: =MiningCapacity_Results!G12*0.003*(1-RoE_Demand!F14) -> 0.42232708 | G14: =MiningCapacity_Results!H12*0.003*(1-RoE_Demand!G14) -> 0.50359833 | H14: =MiningCapacity_Results!I12*0.003*(1-RoE_Demand!H14) -> 0.60050915
A15: Irridium | B15: =MiningCapacity_Results!C13*0.003*(1-RoE_Demand!B15) -> 0.00054 | C15: =MiningCapacity_Results!D13*0.003*(1-RoE_Demand!C15) -> 0.00062905278 | D15: =MiningCapacity_Results!E13*0.003*(1-RoE_Demand!D15) -> 0.00073279148 | E15: =MiningCapacity_Results!F13*0.003*(1-RoE_Demand!E15) -> 0.000853638 | F15: =MiningCapacity_Results!G13*0.003*(1-RoE_Demand!F15) -> 0.00099441362 | G15: =MiningCapacity_Results!H13*0.003*(1-RoE_Demand!G15) -> 0.0011584049 | H15: =MiningCapacity_Results!I13*0.003*(1-RoE_Demand!H15) -> 0.0013494404
A16: Iron | B16: =MiningCapacity_Results!C14*0.003*(1-RoE_Demand!B16) -> 889200 | C16: =MiningCapacity_Results!D14*0.003*(1-RoE_Demand!C16) -> 1073067.9 | D16: =MiningCapacity_Results!E14*0.003*(1-RoE_Demand!D16) -> 1294955.9 | E16: =MiningCapacity_Results!F14*0.003*(1-RoE_Demand!E16) -> 1562725.7 | F16: =MiningCapacity_Results!G14*0.003*(1-RoE_Demand!F16) -> 1885864.6 | G16: =MiningCapacity_Results!H14*0.003*(1-RoE_Demand!G16) -> 2275821.9 | H16: =MiningCapacity_Results!I14*0.003*(1-RoE_Demand!H16) -> 2746414.2
A17: Lead | B17: =MiningCapacity_Results!C15*0.003*(1-RoE_Demand!B17) -> 448.06179 | C17: =MiningCapacity_Results!D15*0.003*(1-RoE_Demand!C17) -> 487.07994 | D17: =MiningCapacity_Results!E15*0.003*(1-RoE_Demand!D17) -> 529.49588 | E17: =MiningCapacity_Results!F15*0.003*(1-RoE_Demand!E17) -> 575.60548 | F17: =MiningCapacity_Results!G15*0.003*(1-RoE_Demand!F17) -> 625.73041 | G17: =MiningCapacity_Results!H15*0.003*(1-RoE_Demand!G17) -> 680.22031 | H17: =MiningCapacity_Results!I15*0.003*(1-RoE_Demand!H17) -> 739.45532
A18: Lanthanum | B18: =MiningCapacity_Results!C16*0.003*(1-RoE_Demand!B18) -> 1.4719604 | C18: =MiningCapacity_Results!D16*0.003*(1-RoE_Demand!C18) -> 1.7482273 | D18: =MiningCapacity_Results!E16*0.003*(1-RoE_Demand!D18) -> 2.0763456 | E18: =MiningCapacity_Results!F16*0.003*(1-RoE_Demand!E18) -> 2.4660472 | F18: =MiningCapacity_Results!G16*0.003*(1-RoE_Demand!F18) -> 2.9288905 | G18: =MiningCapacity_Results!H16*0.003*(1-RoE_Demand!G18) -> 3.4786031 | H18: =MiningCapacity_Results!I16*0.003*(1-RoE_Demand!H18) -> 4.1314893
A19: Lithium | B19: =MiningCapacity_Results!C17*0.003*(1-RoE_Demand!B19) -> 87.615 | C19: =MiningCapacity_Results!D17*0.003*(1-RoE_Demand!C19) -> 316.36396 | D19: =MiningCapacity_Results!E17*0.003*(1-RoE_Demand!D19) -> 708.64679 | E19: =MiningCapacity_Results!F17*0.003*(1-RoE_Demand!E19) -> 696.82705 | F19: =MiningCapacity_Results!G17*0.003*(1-RoE_Demand!F19) -> 666.83688 | G19: =MiningCapacity_Results!H17*0.003*(1-RoE_Demand!G19) -> 900.96999 | H19: =MiningCapacity_Results!I17*0.003*(1-RoE_Demand!H19) -> 1145.7031
A20: Magnesium | B20: =MiningCapacity_Results!C18*0.003*(1-RoE_Demand!B20) -> 141.12 | C20: =MiningCapacity_Results!D18*0.003*(1-RoE_Demand!C20) -> 185.31397 | D20: =MiningCapacity_Results!E18*0.003*(1-RoE_Demand!D20) -> 243.34798 | E20: =MiningCapacity_Results!F18*0.003*(1-RoE_Demand!E20) -> 319.55627 | F20: =MiningCapacity_Results!G18*0.003*(1-RoE_Demand!F20) -> 419.63039 | G20: =MiningCapacity_Results!H18*0.003*(1-RoE_Demand!G20) -> 551.04431 | H20: =MiningCapacity_Results!I18*0.003*(1-RoE_Demand!H20) -> 723.61259
A21: Manganese | B21: =MiningCapacity_Results!C19*0.003*(1-RoE_Demand!B21) -> 2733.7371 | C21: =MiningCapacity_Results!D19*0.003*(1-RoE_Demand!C21) -> 4852.2693 | D21: =MiningCapacity_Results!E19*0.003*(1-RoE_Demand!D21) -> 8788.3425 | E21: =MiningCapacity_Results!F19*0.003*(1-RoE_Demand!E21) -> 13370.521 | F21: =MiningCapacity_Results!G19*0.003*(1-RoE_Demand!F21) -> 18364.139 | G21: =MiningCapacity_Results!H19*0.003*(1-RoE_Demand!G21) -> 26864.49 | H21: =MiningCapacity_Results!I19*0.003*(1-RoE_Demand!H21) -> 34059.535
A22: Molybdenum | B22: =MiningCapacity_Results!C20*0.003*(1-RoE_Demand!B22) -> 126.26865 | C22: =MiningCapacity_Results!D20*0.003*(1-RoE_Demand!C22) -> 142.14602 | D22: =MiningCapacity_Results!E20*0.003*(1-RoE_Demand!D22) -> 213.35982 | E22: =MiningCapacity_Results!F20*0.003*(1-RoE_Demand!E22) -> 300.23535 | F22: =MiningCapacity_Results!G20*0.003*(1-RoE_Demand!F22) -> 337.98779 | G22: =MiningCapacity_Results!H20*0.003*(1-RoE_Demand!G22) -> 456.58479 | H22: =MiningCapacity_Results!I20*0.003*(1-RoE_Demand!H22) -> 513.99704
A23: Neodymium | B23: =MiningCapacity_Results!C21*0.003*(1-RoE_Demand!B23) -> 15.791049 | C23: =MiningCapacity_Results!D21*0.003*(1-RoE_Demand!C23) -> 38.949962 | D23: =MiningCapacity_Results!E21*0.003*(1-RoE_Demand!D23) -> 70.026827 | E23: =MiningCapacity_Results!F21*0.003*(1-RoE_Demand!E23) -> 92.121129 | F23: =MiningCapacity_Results!G21*0.003*(1-RoE_Demand!F23) -> 121.18645 | G23: =MiningCapacity_Results!H21*0.003*(1-RoE_Demand!G23) -> 194.41735 | H23: =MiningCapacity_Results!I21*0.003*(1-RoE_Demand!H23) -> 255.75834
A24: Nickel | B24: =MiningCapacity_Results!C22*0.003*(1-RoE_Demand!B24) -> 711.31269 | C24: =MiningCapacity_Results!D22*0.003*(1-RoE_Demand!C24) -> 1775.1644 | D24: =MiningCapacity_Results!E22*0.003*(1-RoE_Demand!D24) -> 4522.9285 | E24: =MiningCapacity_Results!F22*0.003*(1-RoE_Demand!E24) -> 5509.8394 | F24: =MiningCapacity_Results!G22*0.003*(1-RoE_Demand!F24) -> 6235.18 | G24: =MiningCapacity_Results!H22*0.003*(1-RoE_Demand!G24) -> 7981.858 | H24: =MiningCapacity_Results!I22*0.003*(1-RoE_Demand!H24) -> 10217.838
... A26: Palladium | B26: =MiningCapacity_Results!C24*0.003*(1-RoE_Demand!B26) -> 0.46486507 | C26: =MiningCapacity_Results!D24*0.003*(1-RoE_Demand!C26) -> 0.46486507 | D26: =MiningCapacity_Results!E24*0.003*(1-RoE_Demand!D26) -> 0.43387407 | E26: =MiningCapacity_Results!F24*0.003*(1-RoE_Demand!E26) -> 0.37189206 | F26: =MiningCapacity_Results!G24*0.003*(1-RoE_Demand!F26) -> 0.30991005 | G26: =MiningCapacity_Results!H24*0.003*(1-RoE_Demand!G26) -> 0.24792804 | H26: =MiningCapacity_Results!I24*0.003*(1-RoE_Demand!H26) -> 0.21693703
A27: Polymers
A28: Praesodymium | B28: =MiningCapacity_Results!C25*0.003*(1-RoE_Demand!B28) -> 4.5242177 | C28: =MiningCapacity_Results!D25*0.003*(1-RoE_Demand!C28) -> 11.101797 | D28: =MiningCapacity_Results!E25*0.003*(1-RoE_Demand!D28) -> 19.856576 | E28: =MiningCapacity_Results!F25*0.003*(1-RoE_Demand!E28) -> 25.986803 | F28: =MiningCapacity_Results!G25*0.003*(1-RoE_Demand!F28) -> 34.009586 | G28: =MiningCapacity_Results!H25*0.003*(1-RoE_Demand!G28) -> 54.279519 | H28: =MiningCapacity_Results!I25*0.003*(1-RoE_Demand!H28) -> 71.036979
A29: Platinum | B29: =MiningCapacity_Results!C26*0.003*(1-RoE_Demand!B29) -> 0.1887 | C29: =MiningCapacity_Results!D26*0.003*(1-RoE_Demand!C29) -> 0.20029701 | D29: =MiningCapacity_Results!E26*0.003*(1-RoE_Demand!D29) -> 0.21260674 | E29: =MiningCapacity_Results!F26*0.003*(1-RoE_Demand!E29) -> 0.22567299 | F29: =MiningCapacity_Results!G26*0.003*(1-RoE_Demand!F29) -> 0.23954226 | G29: =MiningCapacity_Results!H26*0.003*(1-RoE_Demand!G29) -> 0.25426391 | H29: =MiningCapacity_Results!I26*0.003*(1-RoE_Demand!H29) -> 0.2698903
A30: Selenium | B30: =MiningCapacity_Results!C27*0.003*(1-RoE_Demand!B30) -> 1.7922 | C30: =MiningCapacity_Results!D27*0.003*(1-RoE_Demand!C30) -> 1.95315 | D30: =MiningCapacity_Results!E27*0.003*(1-RoE_Demand!D30) -> 2.1141 | E30: =MiningCapacity_Results!F27*0.003*(1-RoE_Demand!E30) -> 1.77915 | F30: =MiningCapacity_Results!G27*0.003*(1-RoE_Demand!F30) -> 1.4442 | G30: =MiningCapacity_Results!H27*0.003*(1-RoE_Demand!G30) -> 1.6447131 | H30: =MiningCapacity_Results!I27*0.003*(1-RoE_Demand!H30) -> 1.8730654
A31: Silicon | B31: =MiningCapacity_Results!C28*0.003*(1-RoE_Demand!B31) -> 1800 | C31: =MiningCapacity_Results!D28*0.003*(1-RoE_Demand!C31) -> 5289.5811 | D31: =MiningCapacity_Results!E28*0.003*(1-RoE_Demand!D31) -> 8743.6462 | E31: =MiningCapacity_Results!F28*0.003*(1-RoE_Demand!E31) -> 12847.285 | F31: =MiningCapacity_Results!G28*0.003*(1-RoE_Demand!F31) -> 18876.876 | G31: =MiningCapacity_Results!H28*0.003*(1-RoE_Demand!G31) -> 27736.325 | H31: =MiningCapacity_Results!I28*0.003*(1-RoE_Demand!H31) -> 40753.76
A32: Silver | B32: =MiningCapacity_Results!C29*0.003*(1-RoE_Demand!B32) -> 7.05 | C32: =MiningCapacity_Results!D29*0.003*(1-RoE_Demand!C32) -> 13.492028 | D32: =MiningCapacity_Results!E29*0.003*(1-RoE_Demand!D32) -> 16.081997 | E32: =MiningCapacity_Results!F29*0.003*(1-RoE_Demand!E32) -> 18.104193 | F32: =MiningCapacity_Results!G29*0.003*(1-RoE_Demand!F32) -> 20.380665 | G32: =MiningCapacity_Results!H29*0.003*(1-RoE_Demand!G32) -> 22.943387 | H32: =MiningCapacity_Results!I29*0.003*(1-RoE_Demand!H32) -> 25.828352
A33: Tantalum | B33: =MiningCapacity_Results!C30*0.003*(1-RoE_Demand!B33) -> 0.042097991 | C33: =MiningCapacity_Results!D30*0.003*(1-RoE_Demand!C33) -> 0.061082004 | D33: =MiningCapacity_Results!E30*0.003*(1-RoE_Demand!D33) -> 0.088626824 | E33: =MiningCapacity_Results!F30*0.003*(1-RoE_Demand!E33) -> 0.12859293 | F33: =MiningCapacity_Results!G30*0.003*(1-RoE_Demand!F33) -> 0.18658168 | G33: =MiningCapacity_Results!H30*0.003*(1-RoE_Demand!G33) -> 0.27072036 | H33: =MiningCapacity_Results!I30*0.003*(1-RoE_Demand!H33) -> 0.39280122
A34: Tellurium | B34: =MiningCapacity_Results!C31*0.003*(1-RoE_Demand!B34) -> 0.5506653 | C34: =MiningCapacity_Results!D31*0.003*(1-RoE_Demand!C34) -> 0.75014781 | D34: =MiningCapacity_Results!E31*0.003*(1-RoE_Demand!D34) -> 0.9743568 | E34: =MiningCapacity_Results!F31*0.003*(1-RoE_Demand!E34) -> 0.8199834 | F34: =MiningCapacity_Results!G31*0.003*(1-RoE_Demand!F34) -> 0.66560999 | G34: =MiningCapacity_Results!H31*0.003*(1-RoE_Demand!G34) -> 0.75802344 | H34: =MiningCapacity_Results!I31*0.003*(1-RoE_Demand!H34) -> 0.86326759
A35: Terbium | B35: =MiningCapacity_Results!C32*0.003*(1-RoE_Demand!B35) -> 0.28243204 | C35: =MiningCapacity_Results!D32*0.003*(1-RoE_Demand!C35) -> 0.41235353 | D35: =MiningCapacity_Results!E32*0.003*(1-RoE_Demand!D35) -> 0.58975362 | E35: =MiningCapacity_Results!F32*0.003*(1-RoE_Demand!E35) -> 0.73803944 | F35: =MiningCapacity_Results!G32*0.003*(1-RoE_Demand!F35) -> 0.92360979 | G35: =MiningCapacity_Results!H32*0.003*(1-RoE_Demand!G35) -> 1.1558394 | H35: =MiningCapacity_Results!I32*0.003*(1-RoE_Demand!H35) -> 1.44646
A36: Titanium | B36: =MiningCapacity_Results!C33*0.003*(1-RoE_Demand!B36) -> 147.77997 | C36: =MiningCapacity_Results!D33*0.003*(1-RoE_Demand!C36) -> 181.53241 | D36: =MiningCapacity_Results!E33*0.003*(1-RoE_Demand!D36) -> 668.98135 | E36: =MiningCapacity_Results!F33*0.003*(1-RoE_Demand!E36) -> 1369.624 | F36: =MiningCapacity_Results!G33*0.003*(1-RoE_Demand!F36) -> 1682.4414 | G36: =MiningCapacity_Results!H33*0.003*(1-RoE_Demand!G36) -> 2066.7053 | H36: =MiningCapacity_Results!I33*0.003*(1-RoE_Demand!H36) -> 2538.7337
A37: Tin | B37: =MiningCapacity_Results!C34*0.003*(1-RoE_Demand!B37) -> 275.61414 | C37: =MiningCapacity_Results!D34*0.003*(1-RoE_Demand!C37) -> 305.69041 | D37: =MiningCapacity_Results!E34*0.003*(1-RoE_Demand!D37) -> 339.04874 | E37: =MiningCapacity_Results!F34*0.003*(1-RoE_Demand!E37) -> 376.04729 | F37: =MiningCapacity_Results!G34*0.003*(1-RoE_Demand!F37) -> 417.08329 | G37: =MiningCapacity_Results!H34*0.003*(1-RoE_Demand!G37) -> 462.59732 | H37: =MiningCapacity_Results!I34*0.003*(1-RoE_Demand!H37) -> 513.07805
A38: Tungsten | B38: =MiningCapacity_Results!C35*0.003*(1-RoE_Demand!B38) -> 9.1216469 | C38: =MiningCapacity_Results!D35*0.003*(1-RoE_Demand!C38) -> 10.576927 | D38: =MiningCapacity_Results!E35*0.003*(1-RoE_Demand!D38) -> 12.264384 | E38: =MiningCapacity_Results!F35*0.003*(1-RoE_Demand!E38) -> 14.221061 | F38: =MiningCapacity_Results!G35*0.003*(1-RoE_Demand!F38) -> 16.489909 | G38: =MiningCapacity_Results!H35*0.003*(1-RoE_Demand!G38) -> 19.120731 | H38: =MiningCapacity_Results!I35*0.003*(1-RoE_Demand!H38) -> 22.171279
A39: Vanadium | B39: =MiningCapacity_Results!C36*0.003*(1-RoE_Demand!B39) -> 315 | C39: =MiningCapacity_Results!D36*0.003*(1-RoE_Demand!C39) -> 386.09718 | D39: =MiningCapacity_Results!E36*0.003*(1-RoE_Demand!D39) -> 473.24138 | E39: =MiningCapacity_Results!F36*0.003*(1-RoE_Demand!E39) -> 580.05448 | F39: =MiningCapacity_Results!G36*0.003*(1-RoE_Demand!F39) -> 710.97588 | G39: =MiningCapacity_Results!H36*0.003*(1-RoE_Demand!G39) -> 871.44693 | H39: =MiningCapacity_Results!I36*0.003*(1-RoE_Demand!H39) -> 1068.1372
... A42: Zirconium | B42: =MiningCapacity_Results!C39*0.003*(1-RoE_Demand!B42) -> 17.072134 | C42: =MiningCapacity_Results!D39*0.003*(1-RoE_Demand!C42) -> 24.166462 | D42: =MiningCapacity_Results!E39*0.003*(1-RoE_Demand!D42) -> 34.208838 | E42: =MiningCapacity_Results!F39*0.003*(1-RoE_Demand!E42) -> 48.424326 | F42: =MiningCapacity_Results!G39*0.003*(1-RoE_Demand!F42) -> 68.547061 | G42: =MiningCapacity_Results!H39*0.003*(1-RoE_Demand!G42) -> 97.031802 | H42: =MiningCapacity_Results!I39*0.003*(1-RoE_Demand!H42) -> 137.35338

Sheet RoE_Demand
A1: Demand from rest of economy [%] | B1: 2020 | C1: 2025 | D1: 2030 | E1: 2035 | F1: 2040 | G1: 2045 | H1: 2050 | K1: Source
A2: Aluminum | B2: 0.75 | C2: 0.75 | D2: 0.75 | E2: 0.75 | F2: 0.75 | G2: 0.75 | H2: 0.75 | K2: IAI | L2: Bieuville | M2: Charpentier-Poncelet
A3: Boron | B3: 0.99 | C3: 0.99 | D3: 0.99 | E3: 0.99 | F3: 0.99 | G3: 0.99 | H3: 0.99 | K3: Charpentier-Poncelet | L3: Bieuville
A4: Cadmium | B4: 0.92 | C4: 0.92 | D4: 0.92 | E4: 0.92 | F4: 0.92 | G4: 0.92 | H4: 0.92 | K4: Charpentier-Poncelet | L4: Bieuville
A5: Chromium | B5: 0.8 | C5: 0.8 | D5: 0.8 | E5: 0.8 | F5: 0.8 | G5: 0.8 | H5: 0.8 | K5: Charpentier-Poncelet | L5: Bieuville
A6: Cobalt | B6: 0.57 | C6: 0.57 | D6: 0.43 | E6: 0.43 | F6: 0.43 | G6: 0.43 | H6: 0.43 | K6: https://www.cobaltinstitute.org/wp-content/uploads/2025/05/Cobalt-Market-Report-2024.pdf
A7: Concrete
A8: Copper | B8: 0.8 | C8: 0.8 | D8: 0.8 | E8: 0.75 | F8: 0.75 | G8: 0.75 | H8: 0.75 | K8: Charpentier-Poncelet | L8: Bieuville | M8: https://www.iea.org/data-and-statistics/data-tools/critical-minerals-data-explorer
A9: Dysprosium | B9: 0.75 | C9: 0.7 | D9: 0.65 | E9: 0.6 | F9: 0.55 | G9: 0.5 | H9: 0.45 | K9: Bieuville | L9: https://www.iea.org/data-and-statistics/data-tools/critical-minerals-data-explorer
A10: Gallium | B10: 0.95 | C10: 0.95 | D10: 0.95 | E10: 0.95 | F10: 0.95 | G10: 0.95 | H10: 0.95 | K10: Charpentier-Poncelet | L10: https://www.iea.org/data-and-statistics/data-tools/critical-minerals-data-explorer
A11: Germanium | B11: 0.93 | C11: 0.93 | D11: 0.93 | E11: 0.93 | F11: 0.93 | G11: 0.93 | H11: 0.93 | K11: Charpentier-Poncelet | L11: https://www.iea.org/data-and-statistics/data-tools/critical-minerals-data-explorer
A12: Glass
A13: Hafnium | B13: 0.95 | C13: 0.95 | D13: 0.95 | E13: 0.95 | F13: 0.95 | G13: 0.95 | H13: 0.95 | K13: Charpentier-Poncelet | L13: https://www.iea.org/data-and-statistics/data-tools/critical-minerals-data-explorer
A14: Indium | B14: 0.9 | C14: 0.9 | D14: 0.9 | E14: 0.9 | F14: 0.9 | G14: 0.9 | H14: 0.9 | K14: Charpentier-Poncelet | L14: https://www.iea.org/data-and-statistics/data-tools/critical-minerals-data-explorer
A15: Irridium | B15: 0.97 | C15: 0.97 | D15: 0.97 | E15: 0.97 | F15: 0.97 | G15: 0.97 | H15: 0.97 | K15: Charpentier-Poncelet
A16: Iron | B16: 0.88 | C16: 0.88 | D16: 0.88 | E16: 0.88 | F16: 0.88 | G16: 0.88 | H16: 0.88 | K16: Charpentier-Poncelet
A17: Lead | B17: 0.95 | C17: 0.95 | D17: 0.95 | E17: 0.95 | F17: 0.95 | G17: 0.95 | H17: 0.95 | K17: Charpentier-Poncelet
A18: Lanthanum | B18: 0.99 | C18: 0.99 | D18: 0.99 | E18: 0.99 | F18: 0.99 | G18: 0.99 | H18: 0.99 | K18: Charpentier-Poncelet
A19: Lithium | B19: 0.4 | C19: 0.4 | D19: 0.22 | E19: 0.2 | F19: 0.2 | G19: 0.15 | H19: 0.15 | K19: https://www.iea.org/data-and-statistics/data-tools/critical-minerals-data-explorer
A20: Magnesium | B20: 0.95 | C20: 0.95 | D20: 0.95 | E20: 0.95 | F20: 0.95 | G20: 0.95 | H20: 0.95 | K20: Charpentier-Poncelet
A21: Manganese | B21: 0.95 | C21: 0.93 | D21: 0.9 | E21: 0.88 | F21: 0.87 | G21: 0.85 | H21: 0.85 | K21: Charpentier-Poncelet + hypothèse
A22: Molybdenum | B22: 0.85 | C22: 0.85 | D22: 0.8 | E22: 0.75 | F22: 0.75 | G22: 0.7 | H22: 0.7 | K22: Charpentier-Poncelet + hypothèse
A23: Neodymium | B23: 0.84 | C23: 0.7 | D23: 0.59 | E23: 0.59 | F23: 0.59 | G23: 0.5 | H23: 0.5 | K23: https://www.iea.org/data-and-statistics/charts/total-neodymium-demand-by-sector-and-scenario-2020-2040
A24: Nickel | B24: 0.9 | C24: 0.84 | D24: 0.7 | E24: 0.65 | F24: 0.62 | G24: 0.62 | H24: 0.62 | K24: https://www.iea.org/data-and-statistics/data-tools/critical-minerals-data-explorer
A25: Niobium | B25: 0.9 | C25: 0.9 | D25: 0.9 | E25: 0.9 | F25: 0.9 | G25: 0.9 | H25: 0.9 | K25: Charpentier-Poncelet
A26: Palladium | B26: 0.25 | C26: 0.25 | D26: 0.3 | E26: 0.4 | F26: 0.5 | G26: 0.6 | H26: 0.65 | K26: Charpentier-Poncelet + hypothèse
A27: Polymers
A28: Praesodymium | B28: 0.84 | C28: 0.7 | D28: 0.59 | E28: 0.59 | F28: 0.59 | G28: 0.5 | H28: 0.5 | K28: same as Nd
A29: Platinum | B29: 0.63 | C29: 0.63 | D29: 0.63 | E29: 0.63 | F29: 0.63 | G29: 0.63 | H29: 0.63 | K29: Charpentier-Poncelet + hypothèse
A30: Selenium | B30: 0.9 | C30: 0.9 | D30: 0.9 | E30: 0.9 | F30: 0.9 | G30: 0.9 | H30: 0.9 | K30: Charpentier-Poncelet + hypothèse | L30: https://www.iea.org/data-and-statistics/data-tools/critical-minerals-data-explorer
A31: Silicon | B31: 0.8 | C31: 0.6 | D31: 0.55 | E31: 0.55 | F31: 0.55 | G31: 0.55 | H31: 0.55 | K31: Charpentier-Poncelet + hypothèse | L31: https://www.iea.org/data-and-statistics/data-tools/critical-minerals-data-explorer
A32: Silver | B32: 0.9 | C32: 0.83 | D32: 0.82 | E32: 0.82 | F32: 0.82 | G32: 0.82 | H32: 0.82 | K32: https://www.silverinstitute.org/all-world-silver-surveys/
A33: Tantalum | B33: 0.99 | C33: 0.99 | D33: 0.99 | E33: 0.99 | F33: 0.99 | G33: 0.99 | H33: 0.99 | K33: Charpentier-Poncelet + hypothèse
A34: Tellurium | B34: 0.6 | C34: 0.5 | D34: 0.4 | E34: 0.4 | F34: 0.4 | G34: 0.4 | H34: 0.4 | K34: Charpentier-Poncelet + hypothèse
A35: Terbium | B35: 0.7 | C35: 0.65 | D35: 0.6 | E35: 0.6 | F35: 0.6 | G35: 0.6 | H35: 0.6 | K35: Charpentier-Poncelet + hypothèse
A36: Titanium | B36: 0.99 | C36: 0.99 | D36: 0.97 | E36: 0.95 | F36: 0.95 | G36: 0.95 | H36: 0.95 | K36: Charpentier-Poncelet + hypothèse
A37: Tin
A38: Tungsten | B38: 0.99 | C38: 0.99 | D38: 0.99 | E38: 0.99 | F38: 0.99 | G38: 0.99 | H38: 0.99 | K38: Charpentier-Poncelet + hypothèse
A39: Vanadium
A40: Yttrium
...

Sheet MiningCapacity_Calcul
A1: Metal | B1: Production 2020 world | C1: Unit | D1: Mining flow | E1: Ref | F1: Future prod hypothesis | G1: Beta | H1: Years_considered | I1: Reference
A2: Aluminum | B2: 65100000 | C2: t/yr | D2: Mine production | E2: (USGS, 2021) | F2: Beta | G2: 0.06119989 | H2: All years | I2: (Lundaev et al, 2023)
A3: Boron | B3: 3601490 | C3: t/yr | D3: Mine production | E3: (World Mining Data, 2022) | F3: Beta | G3: 0.049716652 | H3: 1990-2022 / covid | I3: (World Mining Data, 2022)
A4: Cadmium | B4: 24000 | C4: t/yr | D4: Refinery production | E4: (USGS, 2021) | F4: By-product content | G4: (By-product Zn) | I4: (International Cadmium Association, 2021)
A5: Chromium | B5: 37000000 | C5: t/yr | D5: Mine production | E5: (USGS, 2021) | F5: Beta | G5: 0.068181818 | H5: 1990-2022 / covid | I5: (Lundaev et al, 2023)
A6: Cobalt | B6: 142000 | C6: t/yr | D6: Refinery production | E6: (USGS, 2021) | F6: Data IEA until 2040, Beta until 2050 | G6: 0.072442121 | H6: All years | I6: (Lundaev et al, 2023)
A7: Copper | B7: 20600000 | C7: t/yr | D7: Refinery production | E7: (USGS, 2021) | F7: Data IEA until 2040, Beta until 2050 | G7: 0.027417577 | H7: All years | I7: (Lundaev et al, 2023)
A8: Dysprosium | B8: 1121.4732 | C8: t/yr | D8: Mine production | E8: (Lundaev et al, 2023) | F8: Beta | G8: 0.052251758 | H8: 1990-2022 / covid | I8: (Charpentier Poncelet et al., 2022)
A9: Gallium | B9: 327 | C9: t/yr | D9: Mine production | E9: (USGS, 2021) | F9: By-product content | G9: (By-product Al) | I9: (Lundaev et al, 2023; Frenzel et al, 2016)
A10: Germanium | B10: 140 | C10: t/yr | D10: Refinery production | E10: (USGS, 2021) | F10: By-product content | G10: (By-product Zn) | I10: (Frenzel et al, 2014)
A11: Hafnium | B11: 75 | C11: t/yr | D11: Mine production | E11: (Charpentier Poncelet et al., 2022) | F11: Beta | G11: 0.071975973 | H11: Hypothesis, same rate than zirconium | I11: (Charpentier Poncelet et al., 2022)
A12: Indium | B12: 960 | C12: t/yr | D12: Refinery production | E12: (USGS, 2021) | F12: By-product content | G12: (By-product Zn, Cu) | H12: 1990-2022 / covid | I12: (Lundaev et al, 2023)
A13: Irridium | B13: 6 | C13: t/yr | D13: Mine production | E13: (Lundaev et al, 2023) | F13: Beta | G13: 0.031 | H13: 1990-2022 / covid | I13: (Lundaev et al, 2023)
A14: Iron | B14: 2470000000 | C14: t/yr | D14: Mine production | E14: (USGS, 2021) | F14: Beta | G14: 0.038306452 | H14: All years | I14: (USGS, sd*)
A15: Lead | B15: 3120000 | C15: t/yr | D15: Mine production | E15: (USGS, 2021) | F15: Beta | G15: 0.016839639 | H15: All years | I15: (USGS, sd*)
A16: Lanthanum | B16: 53682 | C16: t/yr | D16: Mine production | E16: (Lundaev et al, 2023) | F16: Beta | G16: 0.035 | H16: 1990-2022 / covid | I16: (Lundaev et al, 2023)
A17: Lithium | B17: 82500 | C17: t/yr | D17: Mine production | E17: (USGS, 2021) | F17: Data IEA until 2040, Beta until 2050 | G17: 0.049234 | H17: 1990-2022 / covid | I17: (Charpentier Poncelet et al., 2022)
A18: Magnesium | B18: 1000000 | C18: t/yr | D18: Smelter (primary) production | E18: (USGS, 2021) | F18: Beta | G18: 0.056 | H18: 1990-2022 / covid | I18: (USGS, sd*)
A19: Manganese | B19: 18900000 | C19: t/yr | D19: Mine production | E19: (USGS, 2021) | F19: Beta | G19: 0.048605241 | H19: 1990-2022 / covid | I19: (Lundaev et al, 2023)
A20: Molybdenum | B20: 280597 | C20: t/yr | D20: Mine production | E20: (USGS, 2021) | F20: Beta | G20: 0.023971422 | H20: 1990-2022 | I20: (BGS, sd*)
A21: Neodymium | B21: 34074.892 | C21: t/yr | D21: Mine production | E21: (Lundaev et al, 2023) | F21: Beta | G21: 0.056377058 | H21: 1990-2022 / covid | I21: (Lundaev et al, 2023)
A22: Nickel | B22: 2510000 | C22: t/yr | D22: Mine production | E22: (USGS, 2021) | F22: Data IEA until 2040, Beta until 2050 | G22: 0.050632911 | H22: All years | I22: (Lundaev et al, 2023)
A23: Niobium | B23: 66232 | C23: t/yr | D23: Mine production | E23: (USGS, 2021) | F23: Beta | G23: 0.0087401207 | H23: 1990-2022 / covid | I23: (USGS, sd*)
A24: Palladium | B24: 207 | C24: t/yr | D24: Mine production | E24: (Lundaev et al, 2023) | F24: Beta | G24: 0 | H24: 1990-2022 / covid | I24: (Lundaev et al, 2023)
... A26: Platinum | B26: 170 | C26: t/yr | D26: Mine production | E26: (Lundaev et al, 2023) | F26: Beta | G26: 0.012 | H26: 1990-2022 / covid | I26: (Lundaev et al, 2023)
A27: Selenium | B27: 3120 | C27: t/yr | D27: Refinery production | E27: (USGS, 2021) | F27: By-product ratio content | G27: (By-product Cu) | I27: (Stifner et al, 2024)
A28: Silicon | B28: 3000000 | C28: t/yr | D28: Mine production | E28: (USGS, 2021) | F28: Beta | G28: 0.08 | H28: Hypothesis | I28: (Charpentier Poncelet et al., 2022)
A29: Silver | B29: 23500 | C29: t/yr | D29: Mine production | E29: (USGS, 2021) | F29: Beta | G29: 0.023971422 | H29: 1990-2022 / covid | I29: (Lundaev et al, 2023)
A30: Tantalum | B30: 1406 | C30: t/yr | D30: Mine production | E30: (USGS, 2021) | F30: Beta | G30: 0.077284427 | H30: 1990-2022 / covid | I30: (USGS, sd*)
A31: Tellurium | B31: 562 | C31: t/yr | D31: Refinery production | E31: (USGS, 2021) | F31: By-product ratio content | G31: (By-product Cu) | I31: (Kavlak et Graedel, 2013)
A32: Terbium | B32: 313.81338 | C32: t/yr | D32: Mine production | E32: (Lundaev et al, 2023) | F32: Beta | G32: 0.045879838 | H32: 1990-2022 / covid | I32: (Lundaev et al, 2023)
A33: Titanium | B33: 5154336 | C33: t/yr | D33: Mine production | E33: (Lundaev et al, 2023) | F33: Beta | G33: 0.042 | H33: 1990-2022 | I33: (Lundaev et al, 2023)
A34: Tin | B34: 92572 | C34: t/yr | D34: Mine production | E34: (USGS, 2021) | F34: Beta | G34: 0.020930233 | H34: 1990-2022 / covid | I34: Tin association
A35: Tungsten | B35: 341528.24 | C35: t/yr | D35: Mine production | E35: (USGS, 2021) | F35: Beta | G35: 0.0095350723 | H35: 1990-2022 | I35: (BGS, sd*)
A36: Vanadium | B36: 105000 | C36: t/yr | D36: Mine production | E36: (USGS, 2021) | F36: Beta | G36: 0.041543027 | H36: All years | I36: (Lundaev et al, 2023)
A37: Yttrium | B37: 6423.4613 | C37: t/yr | D37: Mine production | E37: (Lundaev et al, 2023) | F37: Beta | G37: 0.045578176 | H37: 1990-2022 / covid | I37: (Lundaev et al, 2023)
A38: Zinc | B38: 12000000 | C38: t/yr | D38: Mine production | E38: (USGS, 2021) | F38: Beta | G38: 0.037037037 | H38: All years | I38: (Lundaev et al, 2023)
A39: Zirconium | B39: 595238.49 | C39: t/yr | D39: Mine production | E39: (Lundaev et al, 2023) | F39: Beta | G39: 0.071975973 | H39: All years | I39: (Lundaev et al, 2023)
A41: Metal [t] | B41: 2020 | C41: 2030 | D41: 2040 | E41: 2050 | F41: Unit | G41: Ref | H41: Method | I41: Hp
A42: Cobalt | B42: 140000 | C42: 360000 | D42: 259000 | E42: 554016.35 | F42: t/yr | G42: (IEA, 2024) | H42: Data IEA for 2030-2040, Beta until 2050 | I42: New mines opening for 2040
...

Sheet Reserves_Resources_RR
A1: Metals | B1: Resources (estimated) | C1: Confidence level | D1: Ref | E1: Reserves (estimated) | F1: Condifence level | G1: Ref | H1: Unit | I1: RR_Refining | J1: RR_Mining_Refining | K1: Unit | L1: Ref
A2: Aluminum | B2: 26000000000 | C2: Medium | D2: (USGS, 2025 ; Lundaev et al., 2023) | E2: >12000000000 | F2: Medium | G2: (USGS, 2025) | H2: t | I2: 0.90813874 | J2: 0.79852328 | K2: % | L2: (Charpentier-Poncelet, 2022)
A3: Bauxite | B3: 65000000000 | C3: Medium | D3: (USGS, 2025) | E3: 29000000000 | F3: Medium | G3: (USGS, 2025) | H3: t
A4: Boron | B4: Resources estimated sufficient | C4: Medium | D4: (USGS, 2025) | E4: =#N/A -> #N/A | H4: t | I4: 0.9612 | J4: 0.7458912 | K4: % | L4: (Charpentier-Poncelet, 2022)
A5: Cadmium | B5: 5700000 | C5: Low | D5: (Lundaev et al., 2023) | E5: 690000 | F5: Low | G5: (Lundaev et al., 2023) | H5: t | I5: 0.99790607 | J5: 0.76116259 | K5: % | L5: (Charpentier-Poncelet, 2022)
A6: Chromium | B6: 12000000000 | C6: Medium | D6: (USGS, 2025) | E6: 1200000000 | F6: Medium | G6: (USGS, 2025) | H6: t | I6: 0.8921792 | J6: 0.67042368 | K6: % | L6: (Charpentier-Poncelet, 2022)
A7: Cobalt | B7: 25000000 | C7: Medium | D7: (USGS, 2025) | E7: 11000000 | F7: Medium | G7: (USGS, 2025) | H7: t | I7: 0.97064956 | J7: 0.42645155 | K7: % | L7: (Charpentier-Poncelet, 2022)
A8: Copper | B8: 1500000000 | C8: Medium | D8: (USGS, 2025) | E8: 980000000 | F8: Medium | G8: (USGS, 2025) | H8: t | I8: 0.97751656 | J8: 0.8159778 | K8: % | L8: (Charpentier-Poncelet, 2022)
A9: Dysprosium | B9: 4009000 | C9: Low | D9: (Lundaev et al., 2023) | E9: 544000 | F9: Low | G9: (Lundaev et al., 2023) | H9: t | I9: 0.8344547 | J9: 0.55256021 | K9: % | L9: (Charpentier-Poncelet, 2022)
A10: Gallium | B10: 13845000 | C10: Low | D10: (Lundaev et al., 2023) | E10: 1300000 | F10: Low | G10: (USGS, 2025 ; Lundaev et al., 2023) | H10: t | I10: 0.95 | J10: 0.5985 | K10: % | L10: (Nassar & al., 2022)
A11: Germanium | B11: =#N/A -> #N/A | E11: 36000 | F11: Low | G11: (Lundaev et al., 2023) | H11: t | I11: 1 | J11: 0.0065774805 | K11: % | L11: (Charpentier-Poncelet, 2022)
A12: Hafnium | B12: =#N/A -> #N/A | E12: =#N/A -> #N/A | H12: t | I12: 0.99986413 | J12: 0.0027170221 | K12: % | L12: (Charpentier-Poncelet, 2022)
A13: Indium | B13: 356000 | C13: Low | D13: (Lundaev et al., 2023) | E13: 21000 | F13: Low | G13: (Lundaev et al., 2023) | H13: t | I13: 0.83275227 | J13: 0.24982568 | K13: % | L13: (Charpentier-Poncelet, 2022)
A14: Iridium | B14: 2024 | C14: Low | D14: (Lundaev et al., 2023) | E14: 1651 | F14: Low | G14: (Lundaev et al., 2023) | H14: t | I14: 1 | J14: 0.5758 | K14: % | L14: (Charpentier-Poncelet, 2022)
A15: Iron | B15: 230000000000 | C15: Medium | D15: (USGS, 2025) | E15: 88000000000 | F15: Medium | G15: (USGS, 2025) | H15: t | I15: 1 | J15: 0.87408949 | K15: % | L15: (Charpentier-Poncelet, 2022)
A16: Lead | B16: 2000000000 | C16: Medium | D16: (USGS, 2025) | E16: 96000000 | F16: Medium | G16: (USGS, 2025) | H16: t | I16: 0.95739698 | J16: 0.85404163 | K16: % | L16: (Charpentier-Poncelet, 2022)
A17: Lanthanum | B17: 139804561 | C17: Low | D17: (Lundaev et al., 2023) | E17: 25324596 | F17: Low | G17: (Lundaev et al., 2023) | H17: t | I17: 0.914 | J17: 0.5485 | K17: % | L17: (Charpentier-Poncelet, 2022)
A18: Lithium | B18: 115000000 | C18: Medium | D18: (USGS, 2025) | E18: 30000000 | F18: Medium | G18: (USGS, 2025) | H18: t | I18: 0.59 | J18: 0.59 | K18: % | L18: (Nassar & al., 2022)
A19: Magnesium | B19: Resources estimated sufficient | C19: Medium | D19: (USGS, 2025) | E19: #N/A | H19: t | I19: 0.9408 | J19: 0.639 | K19: % | L19: (Charpentier-Poncelet, 2022)
A20: Manganese | B20: 17273000000 | C20: Low | D20: (Lundaev et al., 2023) | E20: 1700000000 | F20: Medium | G20: (USGS, 2025) | H20: t | I20: 0.96428115 | J20: 0.6749968 | K20: % | L20: (Charpentier-Poncelet, 2022)
A21: Molybdenum | B21: 25400000 | C21: Medium | D21: (USGS, 2025) | E21: 15000000 | F21: Medium | G21: (USGS, 2025) | H21: t | I21: 1 | J21: 0.6 | K21: % | L21: (Charpentier-Poncelet, 2022)
A22: Neodymium | B22: 62433000 | C22: Low | D22: (Lundaev et al., 2023) | E22: 16070000 | F22: Low | G22: (Lundaev et al., 2023) | H22: t | I22: 0.96546213 | J22: 0.57787148 | K22: % | L22: (Charpentier-Poncelet, 2022)
A23: Nickel | B23: 350000000 | C23: Medium | D23: (USGS, 2025) | E23: >130000000 | F23: Medium | G23: (USGS, 2025) | H23: t | I23: 0.94463836 | J23: 0.74395466 | K23: % | L23: (Charpentier-Poncelet, 2022)
A24: Niobium | B24: Resources estimated sufficient | C24: Medium | D24: (USGS, 2025) | E24: >17000000 | F24: Medium | G24: (USGS, 2025) | H24: t | I24: 0.92237314 | J24: 0.65488493 | K24: % | L24: (Charpentier-Poncelet, 2022)
A25: Palladium | B25: 40823 | C25: Low | D25: (Lundaev et al., 2023) | E25: 24104 | F25: Low | G25: (Lundaev et al., 2023) | H25: t | I25: 0.9981 | J25: 0.6779 | K25: % | L25: (Charpentier-Poncelet, 2022)
A26: Praesodymium | B26: 19847000 | C26: Low | D26: (Lundaev et al., 2023) | E26: 4718000 | F26: Low | G26: (Lundaev et al., 2023) | H26: t | I26: 0.9029112 | J26: 0.53761582 | K26: % | L26: (Charpentier-Poncelet, 2022)
A27: Platinum | B27: 42102 | C27: Low | D27: (Lundaev et al., 2023) | E27: 31071 | F27: Low | G27: (Lundaev et al., 2023) | H27: t | I27: 1 | J27: 0.6819 | K27: % | L27: (Charpentier-Poncelet, 2022)
A28: Selenium | B28: 171000 | C28: Low | D28: (Watari et al., 2018; USGS, 2017) | E28: 92000 | F28: Medium | G28: (USGS, 2025) | H28: t | I28: 0.99453178 | J28: 0.044752081 | K28: % | L28: (Charpentier-Poncelet, 2022)
A29: Silicon | B29: Resources estimated sufficient | C29: Medium | D29: (USGS, 2025) | E29: =#N/A -> #N/A | H29: t | I29: 0.92 | J29: 0.736 | K29: % | L29: (Charpentier-Poncelet, 2022)
A30: Silver | B30: 1200000 | C30: Low | D30: (Lundaev et al., 2023) | E30: 640000 | F30: Medium | G30: (USGS, 2025) | H30: t | I30: 1 | J30: 0.8425656 | K30: % | L30: (Charpentier-Poncelet, 2022)
A31: Tantalum | B31: Resources estimated sufficient | C31: Medium | D31: (USGS, 2025) | E31: =#N/A -> #N/A | H31: t | I31: 0.99805573 | J31: 0.67785018 | K31: % | L31: (Charpentier-Poncelet, 2022)
A32: Tellurium | B32: 48000 | C32: Low | D32: (Watari et al., 2018; USGS, 2017) | E32: 35000 | F32: Medium | G32: (USGS, 2025) | H32: t | I32: 0.98995007 | J32: 0.044552208 | K32: % | L32: (Charpentier-Poncelet, 2022)
A33: Terbium | B33: 827000 | C33: Low | D33: (Lundaev et al., 2023) | E33: 102000 | F33: Medium | G33: (USGS, 2025) | H33: t | I33: 0.86502679 | J33: 0.55889274 | K33: % | L33: (Charpentier-Poncelet, 2022)
A34: Titanium | B34: 599341397 | C34: Low | D34: (Lundaev et al., 2023) | E34: 449506048 | F34: Low | G34: (Lundaev et al., 2023) | H34: t | I34: 0.9557 | J34: 0.8171 | K34: % | L34: (Charpentier-Poncelet, 2022)
A35: Tin | B35: =#N/A -> #N/A | E35: >4200000 | F35: Medium | G35: (USGS, 2025) | H35: t | I35: 0.99243162 | J35: 0.87567496 | K35: % | L35: (Charpentier-Poncelet, 2022)
A36: Tungsten | B36: =#N/A -> #N/A | E36: 4600000 | F36: Medium | G36: (USGS, 2025) | H36: t | I36: 0.89027747 | J36: 0.29264545 | K36: % | L36: (Charpentier-Poncelet, 2022)
A37: Vanadium | B37: >63000000 | C37: Medium | D37: (USGS, 2025) | E37: 18000000 | F37: Medium | G37: (USGS, 2025) | H37: t | I37: 1 | J37: 0.88571429 | K37: % | L37: (Charpentier-Poncelet, 2022)
A38: Yttrium | B38: 32329000 | C38: Low | D38: (Lundaev et al., 2023) | E38: 3120000 | F38: Low | G38: (Lundaev et al., 2023) | H38: t | I38: 0.8928297 | J38: 0.59290686 | K38: % | L38: (Charpentier-Poncelet, 2022)
A39: Zinc | B39: 1900000000 | C39: Medium | D39: (USGS, 2025) | E39: 230000000 | F39: Medium | G39: (USGS, 2025) | H39: t | I39: 0.97568273 | J39: 0.81742856 | K39: % | L39: (Charpentier-Poncelet, 2022)
A40: Zirconium | B40: =#N/A -> #N/A | E40: >70000000 | F40: Medium | G40: (USGS, 2025) | H40: t | I40: 0.95603887 | J40: 0.81741323 | K40: % | L40: (Charpentier-Poncelet, 2022)

Sheet MiningCapacity_Results
A1: Metal | B1: Production | C1: 2020 | D1: 2025 | E1: 2030 | F1: 2035 | G1: 2040 | H1: 2045 | I1: 2050 | J1: Unit
A2: Aluminum | B2: Primary_Production | C2: 59119832 | D2: 79564470 | E2: 1.0707921e+08 | F2: 1.4410901e+08 | G2: 1.9394434e+08 | H2: 2.6101358e+08 | I2: 3.5127649e+08 | J2: t/yr
A3: Boron | B3: Primary_Production | C3: 3461752.2 | D3: 4412212.4 | E3: 5623631.3 | F3: 7167658 | G3: 9135613.3 | H3: 11643891 | I3: 14840843 | J3: t/yr
A4: Cadmium | B4: Primary_Production | C4: 2673.5515 | D4: 3206.7115 | E4: 3846.1944 | F4: 4613.203 | G4: 5533.1685 | H4: 6636.5938 | I4: 7960.0642 | J4: t/yr
A5: Chromium | B5: Primary_Production | C5: 33010630 | D5: 45907086 | E5: 63841875 | F5: 88783352 | G5: 1.2346886e+08 | H5: 1.7170516e+08 | I5: 2.3878622e+08 | J5: t/yr
A6: Cobalt | B6: Primary_Production | C6: 142000 | D6: 251000 | E6: 360000 | F6: 309500 | G6: 259000 | H6: 378801.05 | I6: 554016.35 | J6: t/yr
A7: Copper | B7: Primary_Production | C7: 20600000 | D7: 22450000 | E7: 24300000 | F7: 20450000 | G7: 16600000 | H7: 18904748 | I7: 21529488 | J7: t/yr
A8: Dysprosium | B8: Primary_Production | C8: 1128.6423 | D8: 1455.9774 | E8: 1878.248 | F8: 2422.9879 | G8: 3125.7162 | H8: 4032.2536 | I8: 5201.71 | J8: t/yr
A9: Gallium | B9: Primary_Production | C9: 779.247 | D9: 1048.7238 | E9: 1411.3902 | F9: 1899.4728 | G9: 2556.3426 | H9: 3440.3691 | I9: 4630.107 | J9: t/yr
A10: Germanium | B10: Primary_Production | C10: 296.4 | D10: 355.50813 | E10: 426.40361 | F10: 511.43707 | G10: 613.42793 | H10: 735.75781 | I10: 882.48273 | J10: t/yr
A11: Hafnium | B11: Primary_Production | C11: 74.98981 | D11: 106.15184 | E11: 150.26325 | F11: 212.70516 | G11: 301.09482 | H11: 426.21481 | I11: 603.32844 | J11: t/yr
A12: Indium | B12: Primary_Production | C12: 806 | D12: 944.2294 | E12: 1106.1652 | F12: 1247.8829 | G12: 1407.7569 | H12: 1678.6611 | I12: 2001.6972 | J12: t/yr
A13: Irridium | B13: Primary_Production | C13: 6 | D13: 6.9894753 | E13: 8.1421276 | F13: 9.4848667 | G13: 11.04904 | H13: 12.871166 | I13: 14.993783 | J13: t/yr
... A39: Zirconium | B39: Primary_Production | C39: 569071.13 | D39: 805548.72 | E39: 1140294.6 | F39: 1614144.2 | G39: 2284902 | H39: 3234393.4 | I39: 4578446 | J39: t/yr

Sheet Ref&Hp
A1: Spreadsheet_name | B1: Data | C1: Ref | E1: Hypothesis
A2: MiningCapacity_Calcul | B2: Prod Beta | C2: (Lundaev et al, 2023) | D2: Lundaev, V., Solomon, A. A., Le, T., Lohrmann, A., & Breyer, C. (2023). Review of critical materials for the energy transition, an analysis of global resources and production databases and the state of material circularity. Minerals Engineering, 203, 108282. https://doi.org/10.1016/j.mineng.2023.108282 | E2: Beta = median of the annual growth rate of historical production. Window "1990-2022 / covid" excludes the 2019 and 2020 growth years. For metals added in this version: Iridium, Palladium, Platinum (Lundaev series 1920-2020, PGE production split by element), Lanthanum (Lundaev series 1975-2020), Titanium (Lundaev series, Ti content of mineral concentrates, beta 1990-2022 = 4.2%).
C3: (USGS, 2021) | D3: U.S. Geological Survey, 2021, Mineral commodity summaries 2021: U.S. Geological Survey, 200 p., https://doi.org/10.3133/mcs2021.
C4: (USGS, sd*) | D4: Historical Statistics for Mineral and Material Commodities in the United States | U.S. Geological Survey. (s. d.). Consulté 30 mai 2024, à l’adresse https://www.usgs.gov/centers/national-minerals-information-center/historical-statistics-mineral-and-material-commodities
C5: (BGS, sd*) | D5: World mineral statistics data | Statistics & Commodities | MineralsUK. (s. d.). Consulté 30 mai 2024, à l’adresse https://www2.bgs.ac.uk/mineralsuk/statistics/wms.cfc?method=searchWMS
C6: (World Mining Data, 2022) | D6: Köstinger, E. (2022). World Mining Data 2022.
C7: (International Tin Association, 2018) | D7: International Tin Association. (2018). Tin for the future: Introduction to the tin market and the International Tin Association. https://www.internationaltin.org/reports/tin-for-the-future/
C8: (USGS Minerals Yearbook, magnesium) | D8: U.S. Geological Survey. Minerals Yearbook, Magnesium (metal), annual volumes 1995, 2000, 2005, 2010, 2015 and 2020 (Table "World primary production, by country"); Mineral Commodity Summaries 2021 and 2023, Magnesium metal. https://www.usgs.gov/centers/national-minerals-information-center/magnesium-statistics-and-information | E8: Magnesium: world primary (smelter) production 1991-2022, world total excluding the United States (data withheld by USGS). Beta 1990-2022 / covid = 5.7%; production has been flat around 1 Mt/yr since 2014, so this beta is an upper-bound trend.
B9: Prod IEA | C9: (IEA, 2024) | D9: Global Critical Minerals Outlook 2024. (2024). | E9: Data IEA for 2030 and 2040 (base case mining capacity); beta applied from 2040 to 2050 (new mines opening).
B10: Prod by-product | C10: (International Cadmium Association, 2021) | D10: International Cadmium Association. (2021, January). Report on worldwide cadmium production and trade 2020. International Cadmium Association. https://www.cadmium.org/wp-content/uploads/2021/11/icda-report-on-worldwide-cadmium-production-and-trade-2020.pdf
C11: (Lu and al., 2017) | D11: Lu, F., Xiao, T., Lin, J., Ning,Z., Long, Q., Xiao, L., Huang,F., Wang, W., Xiao, Q., Lan, X., Chen, H., 2017. Resources and extraction of gallium: A review. Hydrometall. 174, 105–115. https://doi.org/10.1016/j.hydromet.2017.10.010.
C12: (Frenzel and al., 2014) | D12: Frenzel, M., Ketris, M. P., & Gutzmer, J. (2014). On the geological availability of germanium. Mineralium Deposita, 49(4), 471‑486. https://doi.org/10.1007/s00126-013-0506-z
C13: (Frenzel et al, 2016) | D13: Frenzel, M., Ketris, M. P., Seifert, T., & Gutzmer, J. (2016). On the current and future availability of gallium. Resources Policy, 47, 38‑50. https://doi.org/10.1016/j.resourpol.2015.11.005
C14: (Lundaev and al., 2023) | D14: Lundaev, V., Solomon, A. A., Le, T., Lohrmann, A., & Breyer, C. (2023). Review of critical materials for the energy transition, an analysis of global resources and production databases and the state of material circularity. Minerals Engineering, 203, 108282. https://doi.org/10.1016/j.mineng.2023.108282
C15: (Stifner and al., 2024) | D15: Stiftner, R., Weber, L., & Rechberger, H. (2024). Methodology for a better estimation of the reserves and resources of minor metals exemplified by selenium in different copper deposit types. Mineral Economics, 37(3), 413‑432. https://doi.org/10.1007/s13563-023-00384-0
C16: (Kavlak and Graedel, 2013) | D16: Kavlak, G., & Graedel, T. E. (2013). Global anthropogenic tellurium cycles for 1940–2010. Resources, Conservation and Recycling, 76, 21‑26. https://doi.org/10.1016/j.resconrec.2013.04.007
A17: Reserves_Resources_RR | B17: Reserves_Resources | C17: (USGS, 2025) | D17: U.S. Geological Survey, 2025, Mineral commodity summaries 2025 (ver. 1.2, March 2025): U.S. Geological Survey, 212 p., https://doi.org/10.3133/mcs2025 | E17: Individual PGE (Ir, Pd, Pt) reserves and resources are taken from Lundaev et al. (2023), who split USGS PGM totals by element; USGS 2025 only reports PGM as a group (~71 kt reserves, >100 kt resources). Titanium reserves and resources are in Ti content (Lundaev), consistent with the production flow. Magnesium: USGS states reserves are sufficient and resources virtually unlimited.
C18: (Lundaev et al., 2023) | D18: Lundaev, V., Solomon, A. A., Le, T., Lohrmann, A., & Breyer, C. (2023). Review of critical materials for the energy transition, an analysis of global resources and production databases and the state of material circularity. Minerals Engineering, 203, 108282. https://doi.org/10.1016/j.mineng.2023.108282
C19: (Watari et al., 2018) | D19: Watari, T., McLellan, B., Ogata, S., & Tezuka, T. (2018). Analysis of Potential for Critical Metal Resource Constraints in the International Energy Agency’s Long-Term Low-Carbon Energy Scenarios. Minerals, 8(4), 156. https://doi.org/10.3390/min8040156
C20: (Mineral Commodity Summaries 2023, 2023) | D20: (Mineral Commodity Summaries 2023, 2023)
C21: (USGS, 2017) | D21: U.S. Geological Survey (USGS). Historical Statistics for Mineral and Material Commodities in the United States. Available online: https://minerals.usgs.gov/minerals/pubs/historical-statistics/ (accessed on 1 October 2017)
B22: Recovery_rates | C22: (Charpentier-Poncelet, 2022) | D22: Charpentier Poncelet, A., Helbig, C., Loubet, P., Beylot, A., Muller, S., Villeneuve, J., Laratte, B., Thorenz, A., Tuma, A., & Sonnemann, G. (2022). Losses and lifetimes of metals in the economy. Nature Sustainability, 5(8), 717‑726. https://doi.org/10.1038/s41893-022-00895-8 | E22: RR_Refining = 1 − share of cumulative losses in the fabrication phase (Supplementary Data 3, sheet 7 "LossShare per Phase"). RR_Mining_Refining = production yield (sheet 1 "Process yields") × RR_Refining. Exceptions kept from the original file: Lithium (0.59 for both) and Tungsten (0.89 RR_Refining).
C23: (Nassar & al., 2022) | D23: Nassar, N. T., Lederer, G. W., Brainard, J. L., Padilla, A. J., & Lessard, J. D. (2022). Rock-to-Metal Ratio : A Foundational Metric for Understanding Mine Wastes. Environmental Science & Technology, 56(10), 6710‑6721. https://doi.org/10.1021/acs.est.1c07875
A24: Fig 2. MiningCapacity_Results / Material_limits | B24: Primary_Production | C24: / | D24: / | E24: Primary_Production(t) = Production 2020 × (1 + beta)^(t − 2020) × RR_Refining, t = 2020, 2030, 2040, 2050. Co, Cu, Ni, Li: IEA values for 2030 and 2040. By-products: ratio to host × host production (Calcul_Prod). Material_limits = Primary_Production / 1000 (kt/yr), with 2025, 2035, 2045 as linear midpoints between decades.

Sheet Calcul_Prod
C1: Annual historical production [t] | DJ1: Annual growth | HP1: Mean value | HS1: Median value | HW1: Metal | HX1: Beta | HY1: Years_considered
A2: Ref | B2: Metal | C2: 1913 | D2: 1914 | E2: 1915 | F2: 1916 | G2: 1917 | H2: 1918 | I2: 1919 | J2: 1920 | K2: 1921 | L2: 1922 | M2: 1923 | N2: 1924 | O2: 1925 | P2: 1926 | Q2: 1927 | R2: 1928 | S2: 1929 | T2: 1930 | U2: 1931 | V2: 1932 | W2: 1933 | X2: 1934 | Y2: 1935 | Z2: 1936 | AA2: 1937 | AB2: 1938 | AC2: 1939 | AD2: 1940 | AE2: 1941 | AF2: 1942 | AG2: 1943 | AH2: 1944 | AI2: 1945 | AJ2: 1946 | AK2: 1947 | AL2: 1948 | AM2: 1949 | AN2: 1950 | AO2: 1951 | AP2: 1952 | AQ2: 1953 | AR2: 1954 | AS2: 1955 | AT2: 1956 | AU2: 1957 | AV2: 1958 | AW2: 1959 | AX2: 1960 | AY2: 1961 | AZ2: 1962 | BA2: 1963 | BB2: 1964 | BC2: 1965 | BD2: 1966 | BE2: 1967 | BF2: 1968 | BG2: 1969 | BH2: 1970 | BI2: 1971 | BJ2: 1972 | BK2: 1973 | BL2: 1974 | BM2: 1975 | BN2: 1976 | BO2: 1977 | BP2: 1978 | BQ2: 1979 | BR2: 1980 | BS2: 1981 | BT2: 1982 | BU2: 1983 | BV2: 1984 | BW2: 1985 | BX2: 1986 | BY2: 1987 | BZ2: 1988 | CA2: 1989 | CB2: 1990 | CC2: 1991 | CD2: 1992 | CE2: 1993 | CF2: 1994 | CG2: 1995 | CH2: 1996 | CI2: 1997 | CJ2: 1998 | CK2: 1999 | CL2: 2000 | CM2: 2001 | CN2: 2002 | CO2: 2003 | CP2: 2004 | CQ2: 2005 | CR2: 2006 | CS2: 2007 | CT2: 2008 | CU2: 2009 | CV2: 2010 | CW2: 2011 | CX2: 2012 | CY2: 2013 | CZ2: 2014 | DA2: 2015 | DB2: 2016 | DC2: 2017 | DD2: 2018 | DE2: 2019 | DF2: 2020 | DG2: 2021 | DH2: 2022 | DJ2: 1913 | DK2: 1914 | DL2: 1915 | DM2: 1916 | DN2: 1917 | DO2: 1918 | DP2: 1919 | DQ2: 1920 | DR2: 1921 | DS2: 1922 | DT2: 1923 | DU2: 1924 | DV2: 1925 | DW2: 1926 | DX2: 1927 | DY2: 1928 | DZ2: 1929 | EA2: 1930 | EB2: 1931 | EC2: 1932 | ED2: 1933 | EE2: 1934 | EF2: 1935 | EG2: 1936 | EH2: 1937 | EI2: 1938 | EJ2: 1939 | EK2: 1940 | EL2: 1941 | EM2: 1942 | EN2: 1943 | EO2: 1944 | EP2: 1945 | EQ2: 1946 | ER2: 1947 | ES2: 1948 | ET2: 1949 | EU2: 1950 | EV2: 1951 | EW2: 1952 | EX2: 1953 | EY2: 1954 | EZ2: 1955 | FA2: 1956 | FB2: 1957 | FC2: 1958 | FD2: 1959 | FE2: 1960 | FF2: 1961 | FG2: 1962 | FH2: 1963 | FI2: 1964 | FJ2: 1965 | FK2: 1966 | FL2: 1967 | FM2: 1968 | FN2: 1969 | FO2: 1970 | FP2: 1971 | FQ2: 1972 | FR2: 1973 | FS2: 1974 | FT2: 1975 | FU2: 1976 | FV2: 1977 | FW2: 1978 | FX2: 1979 | FY2: 1980 | FZ2: 1981 | GA2: 1982 | GB2: 1983 | GC2: 1984 | GD2: 1985 | GE2: 1986 | GF2: 1987 | GG2: 1988 | GH2: 1989 | GI2: 1990 | GJ2: 1991 | GK2: 1992 | GL2: 1993 | GM2: 1994 | GN2: 1995 | GO2: 1996 | GP2: 1997 | GQ2: 1998 | GR2: 1999 | GS2: 2000 | GT2: 2001 | GU2: 2002 | GV2: 2003 | GW2: 2004 | GX2: 2005 | GY2: 2006 | GZ2: 2007 | HA2: 2008 | HB2: 2009 | HC2: 2010 | HD2: 2011 | HE2: 2012 | HF2: 2013 | HG2: 2014 | HH2: 2015 | HI2: 2016 | HJ2: 2017 | HK2: 2018 | HL2: 2019 | HM2: 2020 | HN2: 2021 | HP2: All years | HQ2: 1990-2022 | HR2: 1990-2022 / covid | HS2: All years | HT2: 1990-2022 | HU2: 1990-2022 / covid
A3: (Lundaev et al, 2023) | B3: Aluminum | C3: 80240.16 | D3: 98700 | E3: 93306.08 | F3: 135133.6 | G3: 176509.76 | H3: 190078.56 | I3: 164640 | J3: 123200 | K3: 81760 | L3: 126560 | M3: 180320 | N3: 185920 | O3: 203840 | P3: 232960 | Q3: 245280 | R3: 267680 | S3: 299040 | T3: 293440 | U3: 243040 | V3: 168000 | W3: 156800 | X3: 187040 | Y3: 285600 | Z3: 392000 | AA3: 554400 | AB3: 647360 | AC3: 757120 | AD3: 865760 | AE3: 1127840 | AF3: 1544480 | AG3: 2160480 | AH3: 1884960 | AI3: 963200 | AJ3: 851200 | AK3: 1198400 | AL3: 1388800 | AM3: 1438080 | AN3: 1643040 | AO3: 1994720 | AP3: 2271360 | AQ3: 2714880 | AR3: 3050880 | AS3: 3472000 | AT3: 3696000 | AU3: 3696000 | AV3: 3920000 | AW3: 4480000 | AX3: 5040000 | AY3: 5152000 | AZ3: 5600000 | BA3: 6048000 | BB3: 6496000 | BC3: 6944000 | BD3: 7504000 | BE3: 8176000 | BF3: 8624000 | BG3: 9632000 | BH3: 9600000 | BI3: 10300000 | BJ3: 10800000 | BK3: 11800000 | BL3: 12700000 | BM3: 12700000 | BN3: 13100000 | BO3: 14200000 | BP3: 14700000 | BQ3: 15200000 | BR3: 16100000 | BS3: 15700000 | BT3: 13900000 | BU3: 14300000 | BV3: 15900000 | BW3: 15600000 | BX3: 15400000 | BY3: 16500000 | BZ3: 17500000 | CA3: 18000000 | CB3: 19300000 | CC3: 19600000 | CD3: 19500000 | CE3: 19700000 | CF3: 19100000 | CG3: 19400000 | CH3: 20700000 | CI3: 21400000 | CJ3: 22100000 | CK3: 23100000 | CL3: 24000000 | CM3: 24400000 | CN3: 25900000 | CO3: 27700000 | CP3: 29800000 | CQ3: 31900000 | CR3: 33700000 | CS3: 38000000 | CT3: 39000000 | CU3: 37300000 | CV3: 40800000 | CW3: 44400000 | CX3: 45900000 | CY3: 47600000 | CZ3: 50500000 | DA3: 57500000 | DB3: 58900000 | DC3: 59400000 | DD3: 63600000 | DE3: 63200000 | DF3: 65100000 | DG3: 68000000 | DK3: =(D3-C3)/C3 -> 0.23005737 | DL3: =(E3-D3)/D3 -> -0.054649645 | DM3: =(F3-E3)/E3 -> 0.4482829 | DN3: =(G3-F3)/F3 -> 0.30618706 | DO3: =(H3-G3)/G3 -> 0.076872803 | DP3: =(I3-H3)/H3 -> -0.13383182 | DQ3: =(J3-I3)/I3 -> -0.25170068 | DR3: =(K3-J3)/J3 -> -0.33636364 | ... HN3: =(DG3-DF3)/DF3 -> 0.044546851 | HP3: =AVERAGE(DK3:HN3) -> 0.076040402 | HQ3: =AVERAGE(GI3:HN3) -> 0.043152543 | HR3: =AVERAGE(GI3:HK3,HN3) -> 0.045236913 | HS3: =MEDIAN($DK3:$HN3) -> 0.062995769 | HT3: =MEDIAN($GI3:$HN3) -> 0.037999038 | HU3: =MEDIAN($GI3:$HK3,$HN3) -> 0.041753945 | HW3: Aluminium | HX3: 0.06119989 | HY3: All years
A4: (World Mining Data, 2022) | B4: Boron | DA4: 4754430 | DB4: 4077557 | DC4: 4228732 | DD4: 4492429 | DE4: 4164758 | DF4: 3601490 | DG4: 4922770 | DH4: 5346091 | HI4: =(DB4-DA4)/DA4 -> -0.1423668 | HJ4: =(DC4-DB4)/DB4 -> 0.037074896 | HK4: =(DD4-DC4)/DC4 -> 0.062358409 | HL4: =(DE4-DD4)/DD4 -> -0.072938493 | HM4: =(DF4-DE4)/DE4 -> -0.13524627 | HN4: =(DG4-DF4)/DF4 -> 0.36687038 | HP4: =AVERAGE(DK4:HN4) -> 0.019292019 | HQ4: =AVERAGE(GI4:HN4) -> 0.019292019 | HR4: =AVERAGE(GI4:HK4,HN4) -> 0.08098422 | HS4: =MEDIAN($DK4:$HN4) -> -0.017931799 | HT4: =MEDIAN($GI4:$HN4) -> -0.017931799 | HU4: =MEDIAN($GI4:$HK4,$HN4) -> 0.049716652 | HW4: Boron | HX4: 0.049716652 | HY4: 1990-2022 / covid
A5: (Lundaev et al, 2023) | B5: Cadmium | M5: 165.6168 | N5: 346 | O5: 346 | P5: 527.292 | Q5: 1544 | R5: 1544 | S5: 2560.3882 | T5: 1654 | U5: 1654 | V5: 748.356 | W5: 4309 | X5: 4309 | Y5: 3560.8817 | Z5: 3789 | AA5: 4017.6026 | AB5: 4664 | AC5: 4664 | AD5: 5310.4918 | AE5: 5885.7837 | AF5: 5011.4711 | AG5: 5490 | AH5: 5968.7035 | AI5: 5735.5675 | AJ5: 5966 | AK5: 5966 | AL5: 6196.4991 | AM5: 6697.7522 | AN5: 5811.2 | AO5: 5811.2 | AP5: 6083.6 | AQ5: 6991.6 | AR5: 6900.8 | AS5: 9296 | AT5: 10080 | AU5: 10640 | AV5: 10080 | AW5: 10080 | AX5: 12320 | AY5: 13440 | AZ5: 13440 | BA5: 13440 | BB5: 14560 | BC5: 14560 | BD5: 14560 | BE5: 16800 | BF5: 16800 | BG5: 19040 | BH5: 19000 | BI5: 18000 | BJ5: 19000 | BK5: 20000 | BL5: 19000 | BM5: 15700 | BN5: 17000 | BO5: 18300 | BP5: 17400 | BQ5: 18200 | BR5: 18200 | BS5: 17200 | BT5: 16500 | BU5: 17200 | BV5: 19200 | BW5: 19400 | BX5: 19300 | BY5: 19300 | BZ5: 21900 | CA5: 21300 | CB5: 20000 | CC5: 20500 | CD5: 20200 | CE5: 18900 | CF5: 18100 | CG5: 18500 | CH5: 18900 | CI5: 20000 | CJ5: 19600 | CK5: 19100 | CL5: 19700 | CM5: 18200 | CN5: 15800 | CO5: 16900 | CP5: 18800 | CQ5: 19400 | CR5: 19300 | CS5: 20400 | CT5: 19600 | CU5: 18800 | CV5: 21100 | CW5: 22200 | CX5: 20900 | CY5: 22200 | CZ5: 24200 | DA5: 23200 | DB5: 23900 | DC5: 25400 | DD5: 25100 | DE5: 24400 | DF5: 24000 | DG5: 24000 | DU5: =(N5-M5)/M5 -> 1.08916 | DV5: =(O5-N5)/N5 -> 0 | DW5: =(P5-O5)/O5 -> 0.52396532 | DX5: =(Q5-P5)/P5 -> 1.9281688 | DY5: =(R5-Q5)/Q5 -> 0 | DZ5: =(S5-R5)/R5 -> 0.65828249 | EA5: =(T5-S5)/S5 -> -0.3540042 | EB5: =(U5-T5)/T5 -> 0 | ... HN5: =(DG5-DF5)/DF5 -> 0 | HP5: =AVERAGE(DK5:HN5) -> 0.10277126 | HQ5: =AVERAGE(GI5:HN5) -> 0.0053736701 | HR5: =AVERAGE(GI5:HK5,HN5) -> 0.0072079777 | HS5: =MEDIAN($DK5:$HN5) -> 0.0052083333 | HT5: =MEDIAN($GI5:$HN5) -> -0.0025773196 | HU5: =MEDIAN($GI5:$HK5,$HN5) -> 0.010810811 | HW5: Cadmium | HX5: (by-product Zn)
