Workbook

Sheet README
A1: Authors | B1: Titouan Greffe and Matthieu Souttre
A2: Last update | B2: 46176
A6: Tabsheet | B6: Content
A7: Brut | B7: Provide value of parameters in EnergyScope model to simulate "Brut" Front Commun scenario (v Éric 1er mai 2026)
A8: Acc_Verte | B8: Provide value of parameters in EnergyScope model to simulate "Accélération Verte" Front Commun scenario (v Éric 1er mai 2026)
A9: Sobre | B9: Provide value of parameters in EnergyScope model to simulate "Sobre" Front Commun scenario (v Éric 1er mai 2026)
A10: Sobre_Lim_Cap | B10: Provide value of parameters in EnergyScope model to simulate "Sobre" Front Commun scenario (v Éric 1er mai 2026) with a limiting constraint on post-combustion carbon capture set to 2 Mt CO2/year.
A11: Value_2023 | B11: Final demand vector Québec in 2023
A12: References | B12: Key references to data set up in "Settings_2050"

Sheet Brut
A1: Parameter | B1: index0_index1 | C1: index0 | D1: index1 | E1: Unit | F1: Value | G1: Comment
A2: end_uses_demand_year | B2: =_xlfn.CONCAT(C2,"_",D2) -> ELECTRICITY_EHV_INDUSTRY | C2: ELECTRICITY_EHV | D2: INDUSTRY | E2: GWh | F2: =v3_Éric!$C$3/100*VLOOKUP(Brut!B2,Value_2023!A:D,4,FALSE) -> 13470.411
A3: end_uses_demand_year | B3: =_xlfn.CONCAT(C3,"_",D3) -> ELECTRICITY_HV_INDUSTRY | C3: ELECTRICITY_HV | D3: INDUSTRY | E3: GWh | F3: =v3_Éric!$C$3/100*VLOOKUP(Brut!B3,Value_2023!A:D,4,FALSE) -> 138692.82
A4: end_uses_demand_year | B4: =_xlfn.CONCAT(C4,"_",D4) -> ELECTRICITY_MV_INDUSTRY | C4: ELECTRICITY_MV | D4: INDUSTRY | E4: GWh | F4: =v3_Éric!$C$3/100*VLOOKUP(Brut!B4,Value_2023!A:D,4,FALSE) -> 21946.957
A5: end_uses_demand_year | B5: =_xlfn.CONCAT(C5,"_",D5) -> HEAT_HIGH_T_INDUSTRY | C5: HEAT_HIGH_T | D5: INDUSTRY | E5: GWh | F5: =v3_Éric!$C$3/100*VLOOKUP(Brut!B5,Value_2023!A:D,4,FALSE) -> 141396.9
A6: end_uses_demand_year | B6: =_xlfn.CONCAT(C6,"_",D6) -> HEAT_LOW_T_HW_INDUSTRY | C6: HEAT_LOW_T_HW | D6: INDUSTRY | E6: GWh | F6: =v3_Éric!$C$3/100*VLOOKUP(Brut!B6,Value_2023!A:D,4,FALSE) -> 1176.936
A7: end_uses_demand_year | B7: =_xlfn.CONCAT(C7,"_",D7) -> HEAT_LOW_T_SH_INDUSTRY | C7: HEAT_LOW_T_SH | D7: INDUSTRY | E7: GWh | F7: =v3_Éric!$C$3/100*VLOOKUP(Brut!B7,Value_2023!A:D,4,FALSE) -> 6154.328
A8: end_uses_demand_year | B8: =_xlfn.CONCAT(C8,"_",D8) -> LIGHTING_INDUSTRY | C8: LIGHTING | D8: INDUSTRY | E8: GWh | F8: =v3_Éric!$C$3/100*VLOOKUP(Brut!B8,Value_2023!A:D,4,FALSE) -> 11113.423
A9: end_uses_demand_year | B9: =_xlfn.CONCAT(C9,"_",D9) -> HEAT_LOW_T_HW_HOUSEHOLDS | C9: HEAT_LOW_T_HW | D9: HOUSEHOLDS | E9: GWh | F9: =v3_Éric!$C$5/100*VLOOKUP(Brut!B9,Value_2023!A:D,4,FALSE) -> 13315.92
A10: end_uses_demand_year | B10: =_xlfn.CONCAT(C10,"_",D10) -> ELECTRICITY_LV_HOUSEHOLDS | C10: ELECTRICITY_LV | D10: HOUSEHOLDS | E10: GWh | F10: =v3_Éric!$C$6/100*VLOOKUP(Brut!B10,Value_2023!A:D,4,FALSE) -> 23542.084
A11: end_uses_demand_year | B11: =_xlfn.CONCAT(C11,"_",D11) -> HEAT_LOW_T_SH_HOUSEHOLDS | C11: HEAT_LOW_T_SH | D11: HOUSEHOLDS | E11: GWh | F11: =v3_Éric!$C$7/100*VLOOKUP(Brut!B11,Value_2023!A:D,4,FALSE) -> 67815.65
A12: end_uses_demand_year | B12: =_xlfn.CONCAT(C12,"_",D12) -> ELECTRICITY_LV_SERVICES | C12: ELECTRICITY_LV | D12: SERVICES | E12: GWh | F12: =v3_Éric!$C$8/100*VLOOKUP(B12,Value_2023!A:D,4,FALSE) -> 13480.548
A13: end_uses_demand_year | B13: =_xlfn.CONCAT(C13,"_",D13) -> ELECTRICITY_MV_SERVICES | C13: ELECTRICITY_MV | D13: SERVICES | E13: GWh | F13: =v3_Éric!$C$8/100*VLOOKUP(B13,Value_2023!A:D,4,FALSE) -> 4228.068
A14: end_uses_demand_year | B14: =_xlfn.CONCAT(C14,"_",D14) -> HEAT_HIGH_T_SERVICES | C14: HEAT_HIGH_T | D14: SERVICES | E14: GWh | F14: =v3_Éric!$C$8/100*VLOOKUP(B14,Value_2023!A:D,4,FALSE) -> 1279.116
A15: end_uses_demand_year | B15: =_xlfn.CONCAT(C15,"_",D15) -> HEAT_LOW_T_HW_SERVICES | C15: HEAT_LOW_T_HW | D15: SERVICES | E15: GWh | F15: =v3_Éric!$C$8/100*VLOOKUP(B15,Value_2023!A:D,4,FALSE) -> 3449.7
A16: end_uses_demand_year | B16: =_xlfn.CONCAT(C16,"_",D16) -> HEAT_LOW_T_SC_SERVICES | C16: HEAT_LOW_T_SC | D16: SERVICES | E16: GWh | F16: =v3_Éric!$C$8/100*VLOOKUP(B16,Value_2023!A:D,4,FALSE) -> 3565.032
A17: end_uses_demand_year | B17: =_xlfn.CONCAT(C17,"_",D17) -> HEAT_LOW_T_SH_SERVICES | C17: HEAT_LOW_T_SH | D17: SERVICES | E17: GWh | F17: =v3_Éric!$C$8/100*VLOOKUP(B17,Value_2023!A:D,4,FALSE) -> 24906.024
A18: end_uses_demand_year | B18: =_xlfn.CONCAT(C18,"_",D18) -> LIGHTING_SERVICES | C18: LIGHTING | D18: SERVICES | E18: GWh | F18: =v3_Éric!$C$8/100*VLOOKUP(B18,Value_2023!A:D,4,FALSE) -> 14443.524
A19: end_uses_demand_year | B19: =_xlfn.CONCAT(C19,"_",D19) -> ELECTRICITY_MV_AGRICULTURE | C19: ELECTRICITY_MV | D19: AGRICULTURE | E19: GWh | F19: =v3_Éric!$C$9/100*VLOOKUP(Brut!B19,Value_2023!A:D,4,FALSE) -> 1789.443
A20: end_uses_demand_year | B20: =_xlfn.CONCAT(C20,"_",D20) -> HEAT_LOW_T_HW_AGRICULTURE | C20: HEAT_LOW_T_HW | D20: AGRICULTURE | E20: GWh | F20: =v3_Éric!$C$9/100*VLOOKUP(Brut!B20,Value_2023!A:D,4,FALSE) -> 109.557
A21: end_uses_demand_year | B21: =_xlfn.CONCAT(C21,"_",D21) -> HEAT_LOW_T_SH_AGRICULTURE | C21: HEAT_LOW_T_SH | D21: AGRICULTURE | E21: GWh | F21: =v3_Éric!$C$9/100*VLOOKUP(Brut!B21,Value_2023!A:D,4,FALSE) -> 986.022
A22: end_uses_demand_year | B22: =_xlfn.CONCAT(C22,"_",D22) -> LIGHTING_AGRICULTURE | C22: LIGHTING | D22: AGRICULTURE | E22: GWh | F22: =v3_Éric!$C$9/100*VLOOKUP(Brut!B22,Value_2023!A:D,4,FALSE) -> 74.556
A23: end_uses_demand_year | B23: =_xlfn.CONCAT(C23,"_",D23) -> MOBILITY_FREIGHT_SD_AGRICULTURE | C23: MOBILITY_FREIGHT_SD | D23: AGRICULTURE | E23: GWh | F23: =v3_Éric!$C$9/100*VLOOKUP(Brut!B23,Value_2023!A:D,4,FALSE) -> 2912.49
A24: end_uses_demand_year | B24: =_xlfn.CONCAT(C24,"_",D24) -> MOBILITY_PASSENGER_LD_TRANSPORTATION | C24: MOBILITY_PASSENGER_LD | D24: TRANSPORTATION | E24: Mpkm | F24: =v3_Éric!C11/100*VLOOKUP(Brut!B24,Value_2023!A:D,4,FALSE) -> 69022.382
A25: end_uses_demand_year | B25: =_xlfn.CONCAT(C25,"_",D25) -> MOBILITY_PASSENGER_MD_TRANSPORTATION | C25: MOBILITY_PASSENGER_MD | D25: TRANSPORTATION | E25: Mpkm | F25: =v3_Éric!C12/100*VLOOKUP(Brut!B25,Value_2023!A:D,4,FALSE) -> 61584.292
A26: end_uses_demand_year | B26: =_xlfn.CONCAT(C26,"_",D26) -> MOBILITY_PASSENGER_SD_TRANSPORTATION | C26: MOBILITY_PASSENGER_SD | D26: TRANSPORTATION | E26: Mpkm | F26: =v3_Éric!C13/100*VLOOKUP(Brut!B26,Value_2023!A:D,4,FALSE) -> 80339.363
A27: end_uses_demand_year | B27: =_xlfn.CONCAT(C27,"_",D27) -> MOBILITY_FREIGHT_ELD_TRANSPORTATION | C27: MOBILITY_FREIGHT_ELD | D27: TRANSPORTATION | E27: Mtkm | F27: =v3_Éric!$C$23/100*VLOOKUP(Brut!B27,Value_2023!A:D,4,FALSE) -> 187327.4
A28: end_uses_demand_year | B28: =_xlfn.CONCAT(C28,"_",D28) -> MOBILITY_FREIGHT_LD_TRANSPORTATION | C28: MOBILITY_FREIGHT_LD | D28: TRANSPORTATION | E28: Mtkm | F28: =v3_Éric!$C$23/100*VLOOKUP(Brut!B28,Value_2023!A:D,4,FALSE) -> 37056.311
A29: end_uses_demand_year | B29: =_xlfn.CONCAT(C29,"_",D29) -> MOBILITY_FREIGHT_MD_TRANSPORTATION | C29: MOBILITY_FREIGHT_MD | D29: TRANSPORTATION | E29: Mtkm | F29: =v3_Éric!$C$23/100*VLOOKUP(Brut!B29,Value_2023!A:D,4,FALSE) -> 48234.508
A30: end_uses_demand_year | B30: =_xlfn.CONCAT(C30,"_",D30) -> MOBILITY_FREIGHT_SD_TRANSPORTATION | C30: MOBILITY_FREIGHT_SD | D30: TRANSPORTATION | E30: Mtkm | F30: =v3_Éric!$C$23/100*VLOOKUP(Brut!B30,Value_2023!A:D,4,FALSE) -> 15231.524
A31: end_uses_demand_year | B31: =_xlfn.CONCAT(C31,"_",D31) -> ELECTRICITY_EHV_EXPORT_EXPORT | C31: ELECTRICITY_EHV_EXPORT | D31: EXPORT | E31: GWh | F31: =v3_Éric!$C$25/100*VLOOKUP(Brut!B31,Value_2023!A:D,4,FALSE) -> 46222.8
A32: out_max | C32: CARBON_CAPTURE | E32: ktCO2 | F32: 1000000
A33: out_max | C33: DAC_LT | E33: ktCO2 | F33: 2000
A34: out_max | C34: DAC_HT | E34: ktCO2 | F34: 2000
A35: avail | C35: NG_EHP | E35: GWh | F35: =v3_Éric!C28/100*'2023_r'!$C2 -> 30670 | G35: imports de gaz naturel
A36: avail | C36: DIESEL | E36: GWh | F36: =v3_Éric!C29/100*'2023_r'!$C3 -> 35850 | G36: import de diesel
A37: avail | C37: GASOLINE | E37: GWh | F37: =v3_Éric!C30/100*'2023_r'!$C4 -> 37420 | G37: import d'essence
A38: avail | C38: LFO | E38: GWh | F38: =v3_Éric!C31/100*'2023_r'!$C5 -> 0 | G38: import de mazout
A39: avail | C39: JETFUEL | E39: GWh | F39: =v3_Éric!C32/100*'2023_r'!$C6 -> 24850 | G39: import de carburant d'aviation
A40: avail | C40: COAL | E40: GWh | F40: =v3_Éric!C33/100*'2023_r'!$C7 -> 0
...

Sheet Acc_Verte
A1: Parameter | B1: index0_index1 | C1: index0 | D1: index1 | E1: Unit | F1: Value | G1: Comment
A2: end_uses_demand_year | B2: =_xlfn.CONCAT(C2,"_",D2) -> ELECTRICITY_EHV_INDUSTRY | C2: ELECTRICITY_EHV | D2: INDUSTRY | E2: GWh | F2: =v3_Éric!$D$3/100*VLOOKUP(Brut!B2,Value_2023!A:D,4,FALSE) -> 14179.38
A3: end_uses_demand_year | B3: =_xlfn.CONCAT(C3,"_",D3) -> ELECTRICITY_HV_INDUSTRY | C3: ELECTRICITY_HV | D3: INDUSTRY | E3: GWh | F3: =v3_Éric!$D$3/100*VLOOKUP(Brut!B3,Value_2023!A:D,4,FALSE) -> 145992.44
A4: end_uses_demand_year | B4: =_xlfn.CONCAT(C4,"_",D4) -> ELECTRICITY_MV_INDUSTRY | C4: ELECTRICITY_MV | D4: INDUSTRY | E4: GWh | F4: =v3_Éric!$D$3/100*VLOOKUP(Brut!B4,Value_2023!A:D,4,FALSE) -> 23102.06
A5: end_uses_demand_year | B5: =_xlfn.CONCAT(C5,"_",D5) -> HEAT_HIGH_T_INDUSTRY | C5: HEAT_HIGH_T | D5: INDUSTRY | E5: GWh | F5: =v3_Éric!$D$3/100*VLOOKUP(Brut!B5,Value_2023!A:D,4,FALSE) -> 148838.84
A6: end_uses_demand_year | B6: =_xlfn.CONCAT(C6,"_",D6) -> HEAT_LOW_T_HW_INDUSTRY | C6: HEAT_LOW_T_HW | D6: INDUSTRY | E6: GWh | F6: =v3_Éric!$D$3/100*VLOOKUP(Brut!B6,Value_2023!A:D,4,FALSE) -> 1238.88
A7: end_uses_demand_year | B7: =_xlfn.CONCAT(C7,"_",D7) -> HEAT_LOW_T_SH_INDUSTRY | C7: HEAT_LOW_T_SH | D7: INDUSTRY | E7: GWh | F7: =v3_Éric!$D$3/100*VLOOKUP(Brut!B7,Value_2023!A:D,4,FALSE) -> 6478.24
A8: end_uses_demand_year | B8: =_xlfn.CONCAT(C8,"_",D8) -> LIGHTING_INDUSTRY | C8: LIGHTING | D8: INDUSTRY | E8: GWh | F8: =v3_Éric!$D$3/100*VLOOKUP(Brut!B8,Value_2023!A:D,4,FALSE) -> 11698.34
A9: end_uses_demand_year | B9: =_xlfn.CONCAT(C9,"_",D9) -> HEAT_LOW_T_HW_HOUSEHOLDS | C9: HEAT_LOW_T_HW | D9: HOUSEHOLDS | E9: GWh | F9: =v3_Éric!$D$5/100*VLOOKUP(Brut!B9,Value_2023!A:D,4,FALSE) -> 6657.96
A10: end_uses_demand_year | B10: =_xlfn.CONCAT(C10,"_",D10) -> ELECTRICITY_LV_HOUSEHOLDS | C10: ELECTRICITY_LV | D10: HOUSEHOLDS | E10: GWh | F10: =v3_Éric!$D$6/100*VLOOKUP(Brut!B10,Value_2023!A:D,4,FALSE) -> 12176.94
A11: end_uses_demand_year | B11: =_xlfn.CONCAT(C11,"_",D11) -> HEAT_LOW_T_SH_HOUSEHOLDS | C11: HEAT_LOW_T_SH | D11: HOUSEHOLDS | E11: GWh | F11: =v3_Éric!$D$7/100*VLOOKUP(Brut!B11,Value_2023!A:D,4,FALSE) -> 27126.26
A12: end_uses_demand_year | B12: =_xlfn.CONCAT(C12,"_",D12) -> ELECTRICITY_LV_SERVICES | C12: ELECTRICITY_LV | D12: SERVICES | E12: GWh | F12: =v3_Éric!$D$8/100*VLOOKUP(B12,Value_2023!A:D,4,FALSE) -> 6740.274
A13: end_uses_demand_year | B13: =_xlfn.CONCAT(C13,"_",D13) -> ELECTRICITY_MV_SERVICES | C13: ELECTRICITY_MV | D13: SERVICES | E13: GWh | F13: =v3_Éric!$D$8/100*VLOOKUP(B13,Value_2023!A:D,4,FALSE) -> 2114.034
A14: end_uses_demand_year | B14: =_xlfn.CONCAT(C14,"_",D14) -> HEAT_HIGH_T_SERVICES | C14: HEAT_HIGH_T | D14: SERVICES | E14: GWh | F14: =v3_Éric!$D$8/100*VLOOKUP(B14,Value_2023!A:D,4,FALSE) -> 639.558
A15: end_uses_demand_year | B15: =_xlfn.CONCAT(C15,"_",D15) -> HEAT_LOW_T_HW_SERVICES | C15: HEAT_LOW_T_HW | D15: SERVICES | E15: GWh | F15: =v3_Éric!$D$8/100*VLOOKUP(B15,Value_2023!A:D,4,FALSE) -> 1724.85
A16: end_uses_demand_year | B16: =_xlfn.CONCAT(C16,"_",D16) -> HEAT_LOW_T_SC_SERVICES | C16: HEAT_LOW_T_SC | D16: SERVICES | E16: GWh | F16: =v3_Éric!$D$8/100*VLOOKUP(B16,Value_2023!A:D,4,FALSE) -> 1782.516
A17: end_uses_demand_year | B17: =_xlfn.CONCAT(C17,"_",D17) -> HEAT_LOW_T_SH_SERVICES | C17: HEAT_LOW_T_SH | D17: SERVICES | E17: GWh | F17: =v3_Éric!$D$8/100*VLOOKUP(B17,Value_2023!A:D,4,FALSE) -> 12453.012
A18: end_uses_demand_year | B18: =_xlfn.CONCAT(C18,"_",D18) -> LIGHTING_SERVICES | C18: LIGHTING | D18: SERVICES | E18: GWh | F18: =v3_Éric!$D$8/100*VLOOKUP(B18,Value_2023!A:D,4,FALSE) -> 7221.762
A19: end_uses_demand_year | B19: =_xlfn.CONCAT(C19,"_",D19) -> ELECTRICITY_MV_AGRICULTURE | C19: ELECTRICITY_MV | D19: AGRICULTURE | E19: GWh | F19: =v3_Éric!$D$9/100*VLOOKUP(Brut!B19,Value_2023!A:D,4,FALSE) -> 1292.3755
A20: end_uses_demand_year | B20: =_xlfn.CONCAT(C20,"_",D20) -> HEAT_LOW_T_HW_AGRICULTURE | C20: HEAT_LOW_T_HW | D20: AGRICULTURE | E20: GWh | F20: =v3_Éric!$D$9/100*VLOOKUP(Brut!B20,Value_2023!A:D,4,FALSE) -> 79.1245
A21: end_uses_demand_year | B21: =_xlfn.CONCAT(C21,"_",D21) -> HEAT_LOW_T_SH_AGRICULTURE | C21: HEAT_LOW_T_SH | D21: AGRICULTURE | E21: GWh | F21: =v3_Éric!$D$9/100*VLOOKUP(Brut!B21,Value_2023!A:D,4,FALSE) -> 712.127
A22: end_uses_demand_year | B22: =_xlfn.CONCAT(C22,"_",D22) -> LIGHTING_AGRICULTURE | C22: LIGHTING | D22: AGRICULTURE | E22: GWh | F22: =v3_Éric!$D$9/100*VLOOKUP(Brut!B22,Value_2023!A:D,4,FALSE) -> 53.846
A23: end_uses_demand_year | B23: =_xlfn.CONCAT(C23,"_",D23) -> MOBILITY_FREIGHT_SD_AGRICULTURE | C23: MOBILITY_FREIGHT_SD | D23: AGRICULTURE | E23: GWh | F23: =v3_Éric!$D$9/100*VLOOKUP(Brut!B23,Value_2023!A:D,4,FALSE) -> 2103.465
A24: end_uses_demand_year | B24: =_xlfn.CONCAT(C24,"_",D24) -> MOBILITY_PASSENGER_LD_TRANSPORTATION | C24: MOBILITY_PASSENGER_LD | D24: TRANSPORTATION | E24: Mpkm | F24: =v3_Éric!D11/100*VLOOKUP(Brut!B24,Value_2023!A:D,4,FALSE) -> 56472.858
A25: end_uses_demand_year | B25: =_xlfn.CONCAT(C25,"_",D25) -> MOBILITY_PASSENGER_MD_TRANSPORTATION | C25: MOBILITY_PASSENGER_MD | D25: TRANSPORTATION | E25: Mpkm | F25: =v3_Éric!D12/100*VLOOKUP(Brut!B25,Value_2023!A:D,4,FALSE) -> 50387.148
A26: end_uses_demand_year | B26: =_xlfn.CONCAT(C26,"_",D26) -> MOBILITY_PASSENGER_SD_TRANSPORTATION | C26: MOBILITY_PASSENGER_SD | D26: TRANSPORTATION | E26: Mpkm | F26: =v3_Éric!D13/100*VLOOKUP(Brut!B26,Value_2023!A:D,4,FALSE) -> 6427.149
A27: end_uses_demand_year | B27: =_xlfn.CONCAT(C27,"_",D27) -> MOBILITY_FREIGHT_ELD_TRANSPORTATION | C27: MOBILITY_FREIGHT_ELD | D27: TRANSPORTATION | E27: Mtkm | F27: =v3_Éric!$D$23/100*VLOOKUP(Brut!B27,Value_2023!A:D,4,FALSE) -> 165288.89
A28: end_uses_demand_year | B28: =_xlfn.CONCAT(C28,"_",D28) -> MOBILITY_FREIGHT_LD_TRANSPORTATION | C28: MOBILITY_FREIGHT_LD | D28: TRANSPORTATION | E28: Mtkm | F28: =v3_Éric!$D$23/100*VLOOKUP(Brut!B28,Value_2023!A:D,4,FALSE) -> 32696.745
A29: end_uses_demand_year | B29: =_xlfn.CONCAT(C29,"_",D29) -> MOBILITY_FREIGHT_MD_TRANSPORTATION | C29: MOBILITY_FREIGHT_MD | D29: TRANSPORTATION | E29: Mtkm | F29: =v3_Éric!$D$23/100*VLOOKUP(Brut!B29,Value_2023!A:D,4,FALSE) -> 42559.86
A30: end_uses_demand_year | B30: =_xlfn.CONCAT(C30,"_",D30) -> MOBILITY_FREIGHT_SD_TRANSPORTATION | C30: MOBILITY_FREIGHT_SD | D30: TRANSPORTATION | E30: Mtkm | F30: =v3_Éric!$D$23/100*VLOOKUP(Brut!B30,Value_2023!A:D,4,FALSE) -> 13439.58
A31: end_uses_demand_year | B31: =_xlfn.CONCAT(C31,"_",D31) -> ELECTRICITY_EHV_EXPORT_EXPORT | C31: ELECTRICITY_EHV_EXPORT | D31: EXPORT | E31: GWh | F31: =v3_Éric!$D$25/100*VLOOKUP(Brut!B31,Value_2023!A:D,4,FALSE) -> 71112
A32: out_max | C32: CARBON_CAPTURE | E32: ktCO2 | F32: 1000000
A33: out_max | C33: DAC_LT | E33: ktCO2 | F33: 2000
A34: out_max | C34: DAC_HT | E34: ktCO2 | F34: 2000
A35: avail | C35: NG_EHP | E35: GWh | F35: =v3_Éric!D28/100*'2023_r'!$C2 -> 0 | G35: imports de gaz naturel
A36: avail | C36: DIESEL | E36: GWh | F36: =v3_Éric!D29/100*'2023_r'!$C3 -> 25095 | G36: import de diesel
A37: avail | C37: GASOLINE | E37: GWh | F37: =v3_Éric!D30/100*'2023_r'!$C4 -> 7484 | G37: import d'essence
A38: avail | C38: LFO | E38: GWh | F38: =v3_Éric!D31/100*'2023_r'!$C5 -> 0 | G38: import de mazout
A39: avail | C39: JETFUEL | E39: GWh | F39: =v3_Éric!D32/100*'2023_r'!$C6 -> 1988 | G39: import de carburant d'aviation
A40: avail | C40: COAL | E40: GWh | F40: =v3_Éric!D33/100*'2023_r'!$C7 -> 0
...

Sheet Sobre
A1: Parameter | B1: index0_index1 | C1: index0 | D1: index1 | E1: Unit | F1: Value | G1: Comment
A2: end_uses_demand_year | B2: =_xlfn.CONCAT(C2,"_",D2) -> ELECTRICITY_EHV_INDUSTRY | C2: ELECTRICITY_EHV | D2: INDUSTRY | E2: GWh | F2: =v3_Éric!$E$3/100*VLOOKUP(Brut!B2,Value_2023!A:D,4,FALSE) -> 4962.783
A3: end_uses_demand_year | B3: =_xlfn.CONCAT(C3,"_",D3) -> ELECTRICITY_HV_INDUSTRY | C3: ELECTRICITY_HV | D3: INDUSTRY | E3: GWh | F3: =v3_Éric!$E$3/100*VLOOKUP(Brut!B3,Value_2023!A:D,4,FALSE) -> 51097.354
A4: end_uses_demand_year | B4: =_xlfn.CONCAT(C4,"_",D4) -> ELECTRICITY_MV_INDUSTRY | C4: ELECTRICITY_MV | D4: INDUSTRY | E4: GWh | F4: =v3_Éric!$E$3/100*VLOOKUP(Brut!B4,Value_2023!A:D,4,FALSE) -> 8085.721
A5: end_uses_demand_year | B5: =_xlfn.CONCAT(C5,"_",D5) -> HEAT_HIGH_T_INDUSTRY | C5: HEAT_HIGH_T | D5: INDUSTRY | E5: GWh | F5: =v3_Éric!$E$3/100*VLOOKUP(Brut!B5,Value_2023!A:D,4,FALSE) -> 52093.594
A6: end_uses_demand_year | B6: =_xlfn.CONCAT(C6,"_",D6) -> HEAT_LOW_T_HW_INDUSTRY | C6: HEAT_LOW_T_HW | D6: INDUSTRY | E6: GWh | F6: =v3_Éric!$E$3/100*VLOOKUP(Brut!B6,Value_2023!A:D,4,FALSE) -> 433.608
A7: end_uses_demand_year | B7: =_xlfn.CONCAT(C7,"_",D7) -> HEAT_LOW_T_SH_INDUSTRY | C7: HEAT_LOW_T_SH | D7: INDUSTRY | E7: GWh | F7: =v3_Éric!$E$3/100*VLOOKUP(Brut!B7,Value_2023!A:D,4,FALSE) -> 2267.384
A8: end_uses_demand_year | B8: =_xlfn.CONCAT(C8,"_",D8) -> LIGHTING_INDUSTRY | C8: LIGHTING | D8: INDUSTRY | E8: GWh | F8: =v3_Éric!$E$3/100*VLOOKUP(Brut!B8,Value_2023!A:D,4,FALSE) -> 4094.419
A9: end_uses_demand_year | B9: =_xlfn.CONCAT(C9,"_",D9) -> HEAT_LOW_T_HW_HOUSEHOLDS | C9: HEAT_LOW_T_HW | D9: HOUSEHOLDS | E9: GWh | F9: =v3_Éric!$E$5/100*VLOOKUP(Brut!B9,Value_2023!A:D,4,FALSE) -> 6657.96
A10: end_uses_demand_year | B10: =_xlfn.CONCAT(C10,"_",D10) -> ELECTRICITY_LV_HOUSEHOLDS | C10: ELECTRICITY_LV | D10: HOUSEHOLDS | E10: GWh | F10: =v3_Éric!$E$6/100*VLOOKUP(Brut!B10,Value_2023!A:D,4,FALSE) -> 8117.96
A11: end_uses_demand_year | B11: =_xlfn.CONCAT(C11,"_",D11) -> HEAT_LOW_T_SH_HOUSEHOLDS | C11: HEAT_LOW_T_SH | D11: HOUSEHOLDS | E11: GWh | F11: =v3_Éric!$E$7/100*VLOOKUP(Brut!B11,Value_2023!A:D,4,FALSE) -> 27126.26
A12: end_uses_demand_year | B12: =_xlfn.CONCAT(C12,"_",D12) -> ELECTRICITY_LV_SERVICES | C12: ELECTRICITY_LV | D12: SERVICES | E12: GWh | F12: =v3_Éric!$E$8/100*VLOOKUP(B12,Value_2023!A:D,4,FALSE) -> 11233.79
A13: end_uses_demand_year | B13: =_xlfn.CONCAT(C13,"_",D13) -> ELECTRICITY_MV_SERVICES | C13: ELECTRICITY_MV | D13: SERVICES | E13: GWh | F13: =v3_Éric!$E$8/100*VLOOKUP(B13,Value_2023!A:D,4,FALSE) -> 3523.39
A14: end_uses_demand_year | B14: =_xlfn.CONCAT(C14,"_",D14) -> HEAT_HIGH_T_SERVICES | C14: HEAT_HIGH_T | D14: SERVICES | E14: GWh | F14: =v3_Éric!$E$8/100*VLOOKUP(B14,Value_2023!A:D,4,FALSE) -> 1065.93
A15: end_uses_demand_year | B15: =_xlfn.CONCAT(C15,"_",D15) -> HEAT_LOW_T_HW_SERVICES | C15: HEAT_LOW_T_HW | D15: SERVICES | E15: GWh | F15: =v3_Éric!$E$8/100*VLOOKUP(B15,Value_2023!A:D,4,FALSE) -> 2874.75
A16: end_uses_demand_year | B16: =_xlfn.CONCAT(C16,"_",D16) -> HEAT_LOW_T_SC_SERVICES | C16: HEAT_LOW_T_SC | D16: SERVICES | E16: GWh | F16: =v3_Éric!$E$8/100*VLOOKUP(B16,Value_2023!A:D,4,FALSE) -> 2970.86
A17: end_uses_demand_year | B17: =_xlfn.CONCAT(C17,"_",D17) -> HEAT_LOW_T_SH_SERVICES | C17: HEAT_LOW_T_SH | D17: SERVICES | E17: GWh | F17: =v3_Éric!$E$8/100*VLOOKUP(B17,Value_2023!A:D,4,FALSE) -> 20755.02
A18: end_uses_demand_year | B18: =_xlfn.CONCAT(C18,"_",D18) -> LIGHTING_SERVICES | C18: LIGHTING | D18: SERVICES | E18: GWh | F18: =v3_Éric!$E$8/100*VLOOKUP(B18,Value_2023!A:D,4,FALSE) -> 12036.27
A19: end_uses_demand_year | B19: =_xlfn.CONCAT(C19,"_",D19) -> ELECTRICITY_MV_AGRICULTURE | C19: ELECTRICITY_MV | D19: AGRICULTURE | E19: GWh | F19: =v3_Éric!$E$9/100*VLOOKUP(Brut!B19,Value_2023!A:D,4,FALSE) -> 2982.405
A20: end_uses_demand_year | B20: =_xlfn.CONCAT(C20,"_",D20) -> HEAT_LOW_T_HW_AGRICULTURE | C20: HEAT_LOW_T_HW | D20: AGRICULTURE | E20: GWh | F20: =v3_Éric!$E$9/100*VLOOKUP(Brut!B20,Value_2023!A:D,4,FALSE) -> 182.595
A21: end_uses_demand_year | B21: =_xlfn.CONCAT(C21,"_",D21) -> HEAT_LOW_T_SH_AGRICULTURE | C21: HEAT_LOW_T_SH | D21: AGRICULTURE | E21: GWh | F21: =v3_Éric!$E$9/100*VLOOKUP(Brut!B21,Value_2023!A:D,4,FALSE) -> 1643.37
A22: end_uses_demand_year | B22: =_xlfn.CONCAT(C22,"_",D22) -> LIGHTING_AGRICULTURE | C22: LIGHTING | D22: AGRICULTURE | E22: GWh | F22: =v3_Éric!$E$9/100*VLOOKUP(Brut!B22,Value_2023!A:D,4,FALSE) -> 124.26
A23: end_uses_demand_year | B23: =_xlfn.CONCAT(C23,"_",D23) -> MOBILITY_FREIGHT_SD_AGRICULTURE | C23: MOBILITY_FREIGHT_SD | D23: AGRICULTURE | E23: GWh | F23: =v3_Éric!$E$9/100*VLOOKUP(Brut!B23,Value_2023!A:D,4,FALSE) -> 4854.15
A24: end_uses_demand_year | B24: =_xlfn.CONCAT(C24,"_",D24) -> MOBILITY_PASSENGER_LD_TRANSPORTATION | C24: MOBILITY_PASSENGER_LD | D24: TRANSPORTATION | E24: Mpkm | F24: =v3_Éric!E11/100*VLOOKUP(Brut!B24,Value_2023!A:D,4,FALSE) -> 41413.429
A25: end_uses_demand_year | B25: =_xlfn.CONCAT(C25,"_",D25) -> MOBILITY_PASSENGER_MD_TRANSPORTATION | C25: MOBILITY_PASSENGER_MD | D25: TRANSPORTATION | E25: Mpkm | F25: =v3_Éric!E12/100*VLOOKUP(Brut!B25,Value_2023!A:D,4,FALSE) -> 36950.575
A26: end_uses_demand_year | B26: =_xlfn.CONCAT(C26,"_",D26) -> MOBILITY_PASSENGER_SD_TRANSPORTATION | C26: MOBILITY_PASSENGER_SD | D26: TRANSPORTATION | E26: Mpkm | F26: =v3_Éric!E13/100*VLOOKUP(Brut!B26,Value_2023!A:D,4,FALSE) -> 6427.149
A27: end_uses_demand_year | B27: =_xlfn.CONCAT(C27,"_",D27) -> MOBILITY_FREIGHT_ELD_TRANSPORTATION | C27: MOBILITY_FREIGHT_ELD | D27: TRANSPORTATION | E27: Mtkm | F27: =v3_Éric!$E$23/100*VLOOKUP(Brut!B27,Value_2023!A:D,4,FALSE) -> 44077.036
A28: end_uses_demand_year | B28: =_xlfn.CONCAT(C28,"_",D28) -> MOBILITY_FREIGHT_LD_TRANSPORTATION | C28: MOBILITY_FREIGHT_LD | D28: TRANSPORTATION | E28: Mtkm | F28: =v3_Éric!$E$23/100*VLOOKUP(Brut!B28,Value_2023!A:D,4,FALSE) -> 8719.132
A29: end_uses_demand_year | B29: =_xlfn.CONCAT(C29,"_",D29) -> MOBILITY_FREIGHT_MD_TRANSPORTATION | C29: MOBILITY_FREIGHT_MD | D29: TRANSPORTATION | E29: Mtkm | F29: =v3_Éric!$E$23/100*VLOOKUP(Brut!B29,Value_2023!A:D,4,FALSE) -> 11349.296
A30: end_uses_demand_year | B30: =_xlfn.CONCAT(C30,"_",D30) -> MOBILITY_FREIGHT_SD_TRANSPORTATION | C30: MOBILITY_FREIGHT_SD | D30: TRANSPORTATION | E30: Mtkm | F30: =v3_Éric!$E$23/100*VLOOKUP(Brut!B30,Value_2023!A:D,4,FALSE) -> 3583.888
A31: end_uses_demand_year | B31: =_xlfn.CONCAT(C31,"_",D31) -> ELECTRICITY_EHV_EXPORT_EXPORT | C31: ELECTRICITY_EHV_EXPORT | D31: EXPORT | E31: GWh | F31: =v3_Éric!$E$25/100*VLOOKUP(Brut!B31,Value_2023!A:D,4,FALSE) -> 17778
A32: out_max | C32: CARBON_CAPTURE | E32: ktCO2 | F32: 1000000
A33: out_max | C33: DAC_LT | E33: ktCO2 | F33: 2000
A34: out_max | C34: DAC_HT | E34: ktCO2 | F34: 2000
A35: avail | C35: NG_EHP | E35: GWh | F35: =v3_Éric!E28/100*'2023_r'!$C2 -> 0 | G35: imports de gaz naturel
A36: avail | C36: DIESEL | E36: GWh | F36: =v3_Éric!E29/100*'2023_r'!$C3 -> 0 | G36: import de diesel
A37: avail | C37: GASOLINE | E37: GWh | F37: =v3_Éric!E30/100*'2023_r'!$C4 -> 0 | G37: import d'essence
A38: avail | C38: LFO | E38: GWh | F38: =v3_Éric!E31/100*'2023_r'!$C5 -> 0 | G38: import de mazout
A39: avail | C39: JETFUEL | E39: GWh | F39: =v3_Éric!E32/100*'2023_r'!$C6 -> 1988 | G39: import de carburant d'aviation
A40: avail | C40: COAL | E40: GWh | F40: =v3_Éric!E33/100*'2023_r'!$C7 -> 0
...

Sheet Sobre_Lim_Cap
A1: Parameter | B1: index0_index1 | C1: index0 | D1: index1 | E1: Unit | F1: Value | G1: Comment
A2: end_uses_demand_year | B2: =_xlfn.CONCAT(C2,"_",D2) -> ELECTRICITY_EHV_INDUSTRY | C2: ELECTRICITY_EHV | D2: INDUSTRY | E2: GWh | F2: =v3_Éric!$E$3/100*VLOOKUP(Brut!B2,Value_2023!A:D,4,FALSE) -> 4962.783
A3: end_uses_demand_year | B3: =_xlfn.CONCAT(C3,"_",D3) -> ELECTRICITY_HV_INDUSTRY | C3: ELECTRICITY_HV | D3: INDUSTRY | E3: GWh | F3: =v3_Éric!$E$3/100*VLOOKUP(Brut!B3,Value_2023!A:D,4,FALSE) -> 51097.354
A4: end_uses_demand_year | B4: =_xlfn.CONCAT(C4,"_",D4) -> ELECTRICITY_MV_INDUSTRY | C4: ELECTRICITY_MV | D4: INDUSTRY | E4: GWh | F4: =v3_Éric!$E$3/100*VLOOKUP(Brut!B4,Value_2023!A:D,4,FALSE) -> 8085.721
A5: end_uses_demand_year | B5: =_xlfn.CONCAT(C5,"_",D5) -> HEAT_HIGH_T_INDUSTRY | C5: HEAT_HIGH_T | D5: INDUSTRY | E5: GWh | F5: =v3_Éric!$E$3/100*VLOOKUP(Brut!B5,Value_2023!A:D,4,FALSE) -> 52093.594
A6: end_uses_demand_year | B6: =_xlfn.CONCAT(C6,"_",D6) -> HEAT_LOW_T_HW_INDUSTRY | C6: HEAT_LOW_T_HW | D6: INDUSTRY | E6: GWh | F6: =v3_Éric!$E$3/100*VLOOKUP(Brut!B6,Value_2023!A:D,4,FALSE) -> 433.608
A7: end_uses_demand_year | B7: =_xlfn.CONCAT(C7,"_",D7) -> HEAT_LOW_T_SH_INDUSTRY | C7: HEAT_LOW_T_SH | D7: INDUSTRY | E7: GWh | F7: =v3_Éric!$E$3/100*VLOOKUP(Brut!B7,Value_2023!A:D,4,FALSE) -> 2267.384
A8: end_uses_demand_year | B8: =_xlfn.CONCAT(C8,"_",D8) -> LIGHTING_INDUSTRY | C8: LIGHTING | D8: INDUSTRY | E8: GWh | F8: =v3_Éric!$E$3/100*VLOOKUP(Brut!B8,Value_2023!A:D,4,FALSE) -> 4094.419
A9: end_uses_demand_year | B9: =_xlfn.CONCAT(C9,"_",D9) -> HEAT_LOW_T_HW_HOUSEHOLDS | C9: HEAT_LOW_T_HW | D9: HOUSEHOLDS | E9: GWh | F9: =v3_Éric!$E$5/100*VLOOKUP(Brut!B9,Value_2023!A:D,4,FALSE) -> 6657.96
A10: end_uses_demand_year | B10: =_xlfn.CONCAT(C10,"_",D10) -> ELECTRICITY_LV_HOUSEHOLDS | C10: ELECTRICITY_LV | D10: HOUSEHOLDS | E10: GWh | F10: =v3_Éric!$E$6/100*VLOOKUP(Brut!B10,Value_2023!A:D,4,FALSE) -> 8117.96
A11: end_uses_demand_year | B11: =_xlfn.CONCAT(C11,"_",D11) -> HEAT_LOW_T_SH_HOUSEHOLDS | C11: HEAT_LOW_T_SH | D11: HOUSEHOLDS | E11: GWh | F11: =v3_Éric!$E$7/100*VLOOKUP(Brut!B11,Value_2023!A:D,4,FALSE) -> 27126.26
A12: end_uses_demand_year | B12: =_xlfn.CONCAT(C12,"_",D12) -> ELECTRICITY_LV_SERVICES | C12: ELECTRICITY_LV | D12: SERVICES | E12: GWh | F12: =v3_Éric!$E$8/100*VLOOKUP(B12,Value_2023!A:D,4,FALSE) -> 11233.79
A13: end_uses_demand_year | B13: =_xlfn.CONCAT(C13,"_",D13) -> ELECTRICITY_MV_SERVICES | C13: ELECTRICITY_MV | D13: SERVICES | E13: GWh | F13: =v3_Éric!$E$8/100*VLOOKUP(B13,Value_2023!A:D,4,FALSE) -> 3523.39
A14: end_uses_demand_year | B14: =_xlfn.CONCAT(C14,"_",D14) -> HEAT_HIGH_T_SERVICES | C14: HEAT_HIGH_T | D14: SERVICES | E14: GWh | F14: =v3_Éric!$E$8/100*VLOOKUP(B14,Value_2023!A:D,4,FALSE) -> 1065.93
A15: end_uses_demand_year | B15: =_xlfn.CONCAT(C15,"_",D15) -> HEAT_LOW_T_HW_SERVICES | C15: HEAT_LOW_T_HW | D15: SERVICES | E15: GWh | F15: =v3_Éric!$E$8/100*VLOOKUP(B15,Value_2023!A:D,4,FALSE) -> 2874.75
A16: end_uses_demand_year | B16: =_xlfn.CONCAT(C16,"_",D16) -> HEAT_LOW_T_SC_SERVICES | C16: HEAT_LOW_T_SC | D16: SERVICES | E16: GWh | F16: =v3_Éric!$E$8/100*VLOOKUP(B16,Value_2023!A:D,4,FALSE) -> 2970.86
A17: end_uses_demand_year | B17: =_xlfn.CONCAT(C17,"_",D17) -> HEAT_LOW_T_SH_SERVICES | C17: HEAT_LOW_T_SH | D17: SERVICES | E17: GWh | F17: =v3_Éric!$E$8/100*VLOOKUP(B17,Value_2023!A:D,4,FALSE) -> 20755.02
A18: end_uses_demand_year | B18: =_xlfn.CONCAT(C18,"_",D18) -> LIGHTING_SERVICES | C18: LIGHTING | D18: SERVICES | E18: GWh | F18: =v3_Éric!$E$8/100*VLOOKUP(B18,Value_2023!A:D,4,FALSE) -> 12036.27
A19: end_uses_demand_year | B19: =_xlfn.CONCAT(C19,"_",D19) -> ELECTRICITY_MV_AGRICULTURE | C19: ELECTRICITY_MV | D19: AGRICULTURE | E19: GWh | F19: =v3_Éric!$E$9/100*VLOOKUP(Brut!B19,Value_2023!A:D,4,FALSE) -> 2982.405
A20: end_uses_demand_year | B20: =_xlfn.CONCAT(C20,"_",D20) -> HEAT_LOW_T_HW_AGRICULTURE | C20: HEAT_LOW_T_HW | D20: AGRICULTURE | E20: GWh | F20: =v3_Éric!$E$9/100*VLOOKUP(Brut!B20,Value_2023!A:D,4,FALSE) -> 182.595
A21: end_uses_demand_year | B21: =_xlfn.CONCAT(C21,"_",D21) -> HEAT_LOW_T_SH_AGRICULTURE | C21: HEAT_LOW_T_SH | D21: AGRICULTURE | E21: GWh | F21: =v3_Éric!$E$9/100*VLOOKUP(Brut!B21,Value_2023!A:D,4,FALSE) -> 1643.37
A22: end_uses_demand_year | B22: =_xlfn.CONCAT(C22,"_",D22) -> LIGHTING_AGRICULTURE | C22: LIGHTING | D22: AGRICULTURE | E22: GWh | F22: =v3_Éric!$E$9/100*VLOOKUP(Brut!B22,Value_2023!A:D,4,FALSE) -> 124.26
A23: end_uses_demand_year | B23: =_xlfn.CONCAT(C23,"_",D23) -> MOBILITY_FREIGHT_SD_AGRICULTURE | C23: MOBILITY_FREIGHT_SD | D23: AGRICULTURE | E23: GWh | F23: =v3_Éric!$E$9/100*VLOOKUP(Brut!B23,Value_2023!A:D,4,FALSE) -> 4854.15
A24: end_uses_demand_year | B24: =_xlfn.CONCAT(C24,"_",D24) -> MOBILITY_PASSENGER_LD_TRANSPORTATION | C24: MOBILITY_PASSENGER_LD | D24: TRANSPORTATION | E24: Mpkm | F24: =v3_Éric!E11/100*VLOOKUP(Brut!B24,Value_2023!A:D,4,FALSE) -> 41413.429
A25: end_uses_demand_year | B25: =_xlfn.CONCAT(C25,"_",D25) -> MOBILITY_PASSENGER_MD_TRANSPORTATION | C25: MOBILITY_PASSENGER_MD | D25: TRANSPORTATION | E25: Mpkm | F25: =v3_Éric!E12/100*VLOOKUP(Brut!B25,Value_2023!A:D,4,FALSE) -> 36950.575
A26: end_uses_demand_year | B26: =_xlfn.CONCAT(C26,"_",D26) -> MOBILITY_PASSENGER_SD_TRANSPORTATION | C26: MOBILITY_PASSENGER_SD | D26: TRANSPORTATION | E26: Mpkm | F26: =v3_Éric!E13/100*VLOOKUP(Brut!B26,Value_2023!A:D,4,FALSE) -> 6427.149
A27: end_uses_demand_year | B27: =_xlfn.CONCAT(C27,"_",D27) -> MOBILITY_FREIGHT_ELD_TRANSPORTATION | C27: MOBILITY_FREIGHT_ELD | D27: TRANSPORTATION | E27: Mtkm | F27: =v3_Éric!$E$23/100*VLOOKUP(Brut!B27,Value_2023!A:D,4,FALSE) -> 44077.036
A28: end_uses_demand_year | B28: =_xlfn.CONCAT(C28,"_",D28) -> MOBILITY_FREIGHT_LD_TRANSPORTATION | C28: MOBILITY_FREIGHT_LD | D28: TRANSPORTATION | E28: Mtkm | F28: =v3_Éric!$E$23/100*VLOOKUP(Brut!B28,Value_2023!A:D,4,FALSE) -> 8719.132
A29: end_uses_demand_year | B29: =_xlfn.CONCAT(C29,"_",D29) -> MOBILITY_FREIGHT_MD_TRANSPORTATION | C29: MOBILITY_FREIGHT_MD | D29: TRANSPORTATION | E29: Mtkm | F29: =v3_Éric!$E$23/100*VLOOKUP(Brut!B29,Value_2023!A:D,4,FALSE) -> 11349.296
A30: end_uses_demand_year | B30: =_xlfn.CONCAT(C30,"_",D30) -> MOBILITY_FREIGHT_SD_TRANSPORTATION | C30: MOBILITY_FREIGHT_SD | D30: TRANSPORTATION | E30: Mtkm | F30: =v3_Éric!$E$23/100*VLOOKUP(Brut!B30,Value_2023!A:D,4,FALSE) -> 3583.888
A31: end_uses_demand_year | B31: =_xlfn.CONCAT(C31,"_",D31) -> ELECTRICITY_EHV_EXPORT_EXPORT | C31: ELECTRICITY_EHV_EXPORT | D31: EXPORT | E31: GWh | F31: =v3_Éric!$E$25/100*VLOOKUP(Brut!B31,Value_2023!A:D,4,FALSE) -> 17778
A32: out_max | C32: CARBON_CAPTURE | E32: ktCO2 | F32: 2000
A33: out_max | C33: DAC_LT | E33: ktCO2 | F33: 0
A34: out_max | C34: DAC_HT | E34: ktCO2 | F34: 0
A35: avail | C35: NG_EHP | E35: GWh | F35: =v3_Éric!E28/100*'2023_r'!$C2 -> 0 | G35: imports de gaz naturel
A36: avail | C36: DIESEL | E36: GWh | F36: =v3_Éric!E29/100*'2023_r'!$C3 -> 0 | G36: import de diesel
A37: avail | C37: GASOLINE | E37: GWh | F37: =v3_Éric!E30/100*'2023_r'!$C4 -> 0 | G37: import d'essence
A38: avail | C38: LFO | E38: GWh | F38: =v3_Éric!E31/100*'2023_r'!$C5 -> 0 | G38: import de mazout
A39: avail | C39: JETFUEL | E39: GWh | F39: =v3_Éric!E32/100*'2023_r'!$C6 -> 1988 | G39: import de carburant d'aviation
A40: avail | C40: COAL | E40: GWh | F40: =v3_Éric!E33/100*'2023_r'!$C7 -> 0
...

Sheet v3_Éric
A1: V3
A2: Variable | B2: Unité | C2: Quebec_brut | D2: Acceleration_verte | E2: Quebec_sobre | F2: index0_index1
A3: INDUSTRY_DEMAND | B3: % vs 2023 | C3: 190 | D3: 200 | E3: 70
A4: HOUSEHOLDS_DEMAND | B4: % vs 2023
A5: Eau chaude | B5: % vs 2023 | C5: 100 | D5: 50 | E5: 50 | F5: HEAT_LOW_T_HW_HOUSEHOLDS
A6: Électricité | B6: % vs 2023 | C6: 145 | D6: 75 | E6: 50 | F6: ELECTRICITY_LV_HOUSEHOLDS
A7: Chauffage | B7: % vs 2023 | C7: 125 | D7: 50 | E7: 50 | F7: HEAT_LOW_T_SH_HOUSEHOLDS
A8: SERVICES_DEMAND | B8: % vs 2023 | C8: 120 | D8: 60 | E8: 100
A9: AGRICULTURE_DEMAND | B9: % vs 2023 | C9: 90 | D9: 65 | E9: 150
A10: MOBILITY_PASSENGER | B10: % vs 2023
A11: court | C11: 110 | D11: 90 | E11: 66
A12: moyen | C12: 110 | D12: 90 | E12: 66
A13: long | C13: 125 | D13: 10 | E13: 10
A14: pour transport court et moyen
A15: CAR_SHARE_PASSENGER | B15: % vs 2023 | C15: 100 | D15: 60 | E15: 20
A16: VUS_SHARE | B16: % vs 2023 | C16: 100 | D16: 20 | E16: 5
A17: EV_SHARE | B17: % vs 2023 | C17: 50 | D17: 100 | E17: 100
A18: VUS_EV | B18: % in 2050 | C18: 0.5 | D18: 0.2 | E18: 0.05 | F18: véhicule hybride?
A19: VUS_ESSENCE | B19: % in 2050 | C19: 0.5 | D19: 0 | E19: 0 | F19: véhicule hybride?
A20: VOITURE_EV | B20: % in 2050 | C20: 0 | D20: 0.8 | E20: 0.95 | F20: véhicule hybride?
A21: VOITURE_ESSENCE | B21: % in 2050 | C21: 0 | D21: 0 | E21: 0 | F21: véhicule hybride?
A22: PT_ACTIVE_SHARE | B22: % vs 2023 | C22: 100 | D22: 200 | E22: 300
A23: MOBILITY_FREIGHT | B23: % vs 2023 | C23: 170 | D23: 150 | E23: 40
A24: RAIL_SHARE_FREIGHT | B24: % vs 2023 | C24: 115 | D24: 175 | E24: 250
A25: EXPORT_ENERGY | B25: % vs 2023 | C25: 130 | D25: 200 | E25: 50
A26: CCS_DEMAND | B26: % vs 2023 | C26: 150 | D26: 175 | E26: 100
A27: FOSSIL FUEL IMPORTS
A28: Gaz | B28: % vs 2023 | C28: 50 | D28: 0 | E28: 0
A29: Diésel | B29: % vs 2023 | C29: 100 | D29: 70 | E29: 0
A30: Essence | B30: % vs 2023 | C30: 50 | D30: 10 | E30: 0
A31: Mazout | B31: % vs 2023 | C31: 0 | D31: 0 | E31: 0
A32: Carburant avion | B32: % vs 2023 | C32: 125 | D32: 10 | E32: 10
A33: Charbon | B33: % vs 2023 | C33: 0 | D33: 0 | E33: 0
A34: bateau, aucune idée | B34: on laisse le modèle calculer?
A36: Données supplémentaires
A37: CCS Demand BAU PGIRE | C37: =15900 -> 15900 | F37: 15.9 million tonnes CO2 par an, fonctionnement 24/24 every day

Sheet Value_2023
A1: index0_index1 | B1: index0 | C1: index1 | D1: end_uses_demand_year | E1: Unit
A2: =_xlfn.CONCAT(B2,"_",C2) -> ELECTRICITY_EHV_INDUSTRY | B2: ELECTRICITY_EHV | C2: INDUSTRY | D2: 7089.69 | E2: GWh
A3: =_xlfn.CONCAT(B3,"_",C3) -> ELECTRICITY_EHV_EXPORT_EXPORT | B3: ELECTRICITY_EHV_EXPORT | C3: EXPORT | D3: 35556 | E3: GWh
A4: =_xlfn.CONCAT(B4,"_",C4) -> ELECTRICITY_HV_INDUSTRY | B4: ELECTRICITY_HV | C4: INDUSTRY | D4: 72996.22 | E4: GWh
A5: =_xlfn.CONCAT(B5,"_",C5) -> ELECTRICITY_LV_HOUSEHOLDS | B5: ELECTRICITY_LV | C5: HOUSEHOLDS | D5: 16235.92 | E5: GWh
A6: =_xlfn.CONCAT(B6,"_",C6) -> ELECTRICITY_LV_SERVICES | B6: ELECTRICITY_LV | C6: SERVICES | D6: 11233.79 | E6: GWh
A7: =_xlfn.CONCAT(B7,"_",C7) -> ELECTRICITY_MV_AGRICULTURE | B7: ELECTRICITY_MV | C7: AGRICULTURE | D7: 1988.27 | E7: GWh
A8: =_xlfn.CONCAT(B8,"_",C8) -> ELECTRICITY_MV_INDUSTRY | B8: ELECTRICITY_MV | C8: INDUSTRY | D8: 11551.03 | E8: GWh
A9: =_xlfn.CONCAT(B9,"_",C9) -> ELECTRICITY_MV_SERVICES | B9: ELECTRICITY_MV | C9: SERVICES | D9: 3523.39 | E9: GWh
A10: =_xlfn.CONCAT(B10,"_",C10) -> HEAT_HIGH_T_INDUSTRY | B10: HEAT_HIGH_T | C10: INDUSTRY | D10: 74419.42 | E10: GWh
A11: =_xlfn.CONCAT(B11,"_",C11) -> HEAT_HIGH_T_SERVICES | B11: HEAT_HIGH_T | C11: SERVICES | D11: 1065.93 | E11: GWh
A12: =_xlfn.CONCAT(B12,"_",C12) -> HEAT_LOW_T_HW_AGRICULTURE | B12: HEAT_LOW_T_HW | C12: AGRICULTURE | D12: 121.73 | E12: GWh
A13: =_xlfn.CONCAT(B13,"_",C13) -> HEAT_LOW_T_HW_HOUSEHOLDS | B13: HEAT_LOW_T_HW | C13: HOUSEHOLDS | D13: 13315.92 | E13: GWh
... A34: =_xlfn.CONCAT(B34,"_",C34) -> ELECTRICITY_EHV_EXPORT_EXPORT | B34: ELECTRICITY_EHV_EXPORT | C34: EXPORT | D34: 35.56 | E34: GWh

Sheet 2023_r
A1: Variable or parameter | B1: index0 | C1: Value | D1: Unit
A2: Annual_Res | B2: NG_EHP | C2: =61.34*1000 -> 61340 | D2: GWh
A3: Annual_Res | B3: DIESEL | C3: =35.85*1000 -> 35850 | D3: GWh
A4: Annual_Res | B4: GASOLINE | C4: =74.84*1000 -> 74840 | D4: GWh
A5: Annual_Res | B5: LFO | C5: =26.49*1000 -> 26490 | D5: GWh
A6: Annual_Res | B6: JETFUEL | C6: =19.88*1000 -> 19880 | D6: GWh
A7: Annual_Res | B7: COAL | C7: 3420 | D7: GWh
A8: share_freight_rail_min/max_ld | C8: =37.23/100 -> 0.3723 | D8: -
A9: share_freight_rail_min/max_eld | C9: =22.09/100 -> 0.2209 | D9: -
A10: share_freight_maritime_min/max_eld | C10: 0.5879 | D10: -
A11: share_freight_air_min/max_eld | C11: 0.0063 | D11: -
A12: share_mobility_public_min/max_sd | C12: 0.1146 | D12: -

Sheet References
A1: # | B1: Citation
A2: 1
